Workbook

Sheet pokemon
A1: pokedex_number | B1: pokedex_name | C1: type_1 | D1: type_2 | E1: hp | F1: atk | G1: def | H1: sp_atk | I1: sp_def | J1: spd | K1: classification | L1: biome | M1: climate | N1: _initiative | O1: _health | P1: i_mod | Q1: h_mod | R1: initiative | S1: health | T1: total | U1: move_1 | V1: move_2 | W1: move_3 | X1: move_4 | Y1: evolve_into | Z1: evolve_cost | AA1: internal_name | AB1: description | AC1: move_name | AD1: move_type | AE1: move_attack_strength | AF1: move_effect | AG1: is_starter | AH1: is_legendary | AI1: encounter_tier | AJ1: trainer | AK1: number_in_deck | AL1: uncapturable | AM1: state
A2: 387 | B2: Turtwig | C2: grass | E2: 55 | F2: 68 | G2: 64 | H2: 45 | I2: 55 | J2: 31 | K2: Tiny Leaf Pokémon | L2: Forest | M2: Temperate | N2: =(0.4*J2 + 0.5*MAX(F2,H2) + 0.1*MIN(F2,H2)) / 10 -> 5.09 | O2: =(0.4*E2 + 0.3*G2 + 0.3*I2) / 10 -> 5.77 | P2: -1 | Q2: 0 | R2: =ROUND(N2,0)+P2 -> 4 | S2: =ROUND(O2,0)+Q2 -> 6 | T2: =SUM(ROUND(R2,0),ROUND(S2,0)) -> 10 | U2: =C2 -> grass | V2: ground | W2: dark | X2: normal | Y2: =B3 -> Grotle | Z2: =IF(ISBLANK(Y2), "", ROUND(( (T3-6)*(T3-7) - (T2-6)*(T2-7) )/15, 0) + 1) -> 4 | AA2: =B2 -> Turtwig | AC2: Razor Leaf | AD2: =VLOOKUP(AC2,moves!A:B,2,FALSE) -> grass | AE2: =VLOOKUP(AC2,moves!A:D,4,FALSE) -> 3 | AF2: =VLOOKUP(AC2,moves!A:F,5,FALSE) -> 0 | AG2: 1 | AH2: 0 | AI2: {=_xlfn.IFS(AG2=1, "starter", AH2=1, "legendary",T2< 13, "weak",T2< 17, "moderate", TRUE, "strong")} -> starter | AK2: 1 | AL2: 0 | AM2: 0
A3: 388 | B3: Grotle | C3: grass | E3: 75 | F3: 89 | G3: 85 | H3: 55 | I3: 65 | J3: 36 | K3: Grove Pokémon | L3: Forest | M3: Temperate | N3: =(0.4*J3 + 0.5*MAX(F3,H3) + 0.1*MIN(F3,H3)) / 10 -> 6.44 | O3: =(0.4*E3 + 0.3*G3 + 0.3*I3) / 10 -> 7.5 | P3: 0 | Q3: 0 | R3: =ROUND(N3,0)+P3 -> 6 | S3: =ROUND(O3,0)+Q3 -> 8 | T3: =SUM(ROUND(R3,0),ROUND(S3,0)) -> 14 | U3: =C3 -> grass | V3: ground | W3: dark | X3: normal | Y3: =B4 -> Torterra | Z3: =IF(ISBLANK(Y3), "", ROUND(( (T4-6)*(T4-7) - (T3-6)*(T3-7) )/15, 0) + 1) -> 6 | AA3: =B3 -> Grotle | AC3: Bite | AD3: =VLOOKUP(AC3,moves!A:B,2,FALSE) -> dark | AE3: =VLOOKUP(AC3,moves!A:D,4,FALSE) -> 3 | AF3: =VLOOKUP(AC3,moves!A:F,5,FALSE) -> 0 | AG3: 0 | AH3: 0 | AI3: {=_xlfn.IFS(AG3=1, "starter", AH3=1, "legendary",T3< 13, "weak",T3< 17, "moderate", TRUE, "strong")} -> moderate | AK3: 2 | AL3: 0 | AM3: 0
A4: 389 | B4: Torterra | C4: grass | D4: ground | E4: 95 | F4: 109 | G4: 105 | H4: 75 | I4: 85 | J4: 56 | K4: Continent Pokémon | L4: Forest | M4: Temperate | N4: =(0.4*J4 + 0.5*MAX(F4,H4) + 0.1*MIN(F4,H4)) / 10 -> 8.44 | O4: =(0.4*E4 + 0.3*G4 + 0.3*I4) / 10 -> 9.5 | P4: 0 | Q4: 0 | R4: =ROUND(N4,0)+P4 -> 8 | S4: =ROUND(O4,0)+Q4 -> 10 | T4: =SUM(ROUND(R4,0),ROUND(S4,0)) -> 18 | U4: =C4 -> grass | V4: =IF(D4 = 0, "", D4) -> ground | W4: dark | X4: normal | Z4: =IF(ISBLANK(Y4), "", ROUND(( (T6-6)*(T6-7) - (T4-6)*(T4-7) )/15, 0) + 1) | AA4: =B4 -> Torterra | AC4: Headlong Rush | AD4: =VLOOKUP(AC4,moves!A:B,2,FALSE) -> ground | AE4: =VLOOKUP(AC4,moves!A:D,4,FALSE) -> 5 | AF4: =VLOOKUP(AC4,moves!A:F,5,FALSE) -> 0 | AG4: 0 | AH4: 0 | AI4: {=_xlfn.IFS(AG4=1, "starter", AH4=1, "legendary",T4< 13, "weak",T4< 17, "moderate", TRUE, "strong")} -> strong | AK4: 3 | AL4: 0 | AM4: 1
A5: 389-n | B5: Torterra | C5: grass | D5: ground | E5: 95 | F5: 109 | G5: 105 | H5: 75 | I5: 85 | J5: 56 | K5: Continent Pokémon | M5: Noble | N5: =(0.4*J5 + 0.5*MAX(F5,H5) + 0.1*MIN(F5,H5)) / 10 -> 8.44 | O5: =(0.4*E5 + 0.3*G5 + 0.3*I5) / 10 -> 9.5 | P5: 2 | Q5: 2 | R5: =ROUND(N5,0)+P5 -> 10 | S5: =ROUND(O5,0)+Q5 -> 12 | T5: =SUM(ROUND(R5,0),ROUND(S5,0)) -> 22 | U5: =C5 -> grass | V5: =IF(D5 = 0, "", D5) -> ground | W5: dark | X5: normal | AA5: =B5 -> Torterra | AB5: Noble Form | AC5: Headlong Rush | AD5: =VLOOKUP(AC5,moves!A:B,2,FALSE) -> ground | AE5: =VLOOKUP(AC5,moves!A:D,4,FALSE) -> 5 | AF5: =VLOOKUP(AC5,moves!A:F,5,FALSE) -> 0 | AG5: 0 | AH5: 1 | AI5: {=_xlfn.IFS(AG5=1, "starter", AH5=1, "legendary",T5< 13, "weak",T5< 17, "moderate", TRUE, "strong")} -> legendary | AK5: 3 | AL5: 0 | AM5: 2
A6: 390 | B6: Chimchar | C6: fire | E6: 44 | F6: 58 | G6: 44 | H6: 58 | I6: 44 | J6: 61 | K6: Chimp Pokémon | L6: Forest | M6: Warm | N6: =(0.4*J6 + 0.5*MAX(F6,H6) + 0.1*MIN(F6,H6)) / 10 -> 5.92 | O6: =(0.4*E6 + 0.3*G6 + 0.3*I6) / 10 -> 4.4 | P6: 0 | Q6: 0 | R6: =ROUND(N6,0)+P6 -> 6 | S6: =ROUND(O6,0)+Q6 -> 4 | T6: =SUM(ROUND(R6,0),ROUND(S6,0)) -> 10 | U6: =C6 -> fire | V6: fighting | W6: rock | X6: flying | Y6: =B7 -> Monferno | Z6: =IF(ISBLANK(Y6), "", ROUND(( (T7-6)*(T7-7) - (T6-6)*(T6-7) )/15, 0) + 1) -> 4 | AA6: =B6 -> Chimchar | AC6: Ember | AD6: =VLOOKUP(AC6,moves!A:B,2,FALSE) -> fire | AE6: =VLOOKUP(AC6,moves!A:D,4,FALSE) -> 2 | AF6: =VLOOKUP(AC6,moves!A:F,5,FALSE) -> 0 | AG6: 1 | AH6: 0 | AI6: {=_xlfn.IFS(AG6=1, "starter", AH6=1, "legendary",T6< 13, "weak",T6< 17, "moderate", TRUE, "strong")} -> starter | AK6: 1 | AL6: 0 | AM6: 0
A7: 391 | B7: Monferno | C7: fire | D7: fighting | E7: 64 | F7: 78 | G7: 52 | H7: 78 | I7: 52 | J7: 81 | K7: Playful Pokémon | L7: Forest | M7: Warm | N7: =(0.4*J7 + 0.5*MAX(F7,H7) + 0.1*MIN(F7,H7)) / 10 -> 7.92 | O7: =(0.4*E7 + 0.3*G7 + 0.3*I7) / 10 -> 5.68 | P7: 0 | Q7: 0 | R7: =ROUND(N7,0)+P7 -> 8 | S7: =ROUND(O7,0)+Q7 -> 6 | T7: =SUM(ROUND(R7,0),ROUND(S7,0)) -> 14 | U7: =C7 -> fire | V7: =IF(D7 = 0, "", D7) -> fighting | W7: rock | X7: flying | Y7: =B8 -> Infernape | Z7: =IF(ISBLANK(Y7), "", ROUND(( (T8-6)*(T8-7) - (T7-6)*(T7-7) )/15, 0) + 1) -> 6 | AA7: =B7 -> Monferno | AC7: Mach Punch | AD7: =VLOOKUP(AC7,moves!A:B,2,FALSE) -> fighting | AE7: =VLOOKUP(AC7,moves!A:D,4,FALSE) -> 2 | AF7: =VLOOKUP(AC7,moves!A:F,5,FALSE) -> agile | AG7: 0 | AH7: 0 | AI7: {=_xlfn.IFS(AG7=1, "starter", AH7=1, "legendary",T7< 13, "weak",T7< 17, "moderate", TRUE, "strong")} -> moderate | AK7: 2 | AL7: 0 | AM7: 0
A8: 392 | B8: Infernape | C8: fire | D8: fighting | E8: 76 | F8: 104 | G8: 71 | H8: 104 | I8: 71 | J8: 108 | K8: Flame Pokémon | L8: Forest | M8: Warm | N8: =(0.4*J8 + 0.5*MAX(F8,H8) + 0.1*MIN(F8,H8)) / 10 -> 10.56 | O8: =(0.4*E8 + 0.3*G8 + 0.3*I8) / 10 -> 7.3 | P8: 0 | Q8: 0 | R8: =ROUND(N8,0)+P8 -> 11 | S8: =ROUND(O8,0)+Q8 -> 7 | T8: =SUM(ROUND(R8,0),ROUND(S8,0)) -> 18 | U8: =C8 -> fire | V8: =IF(D8 = 0, "", D8) -> fighting | W8: rock | X8: flying | Z8: =IF(ISBLANK(Y8), "", ROUND(( (T10-6)*(T10-7) - (T8-6)*(T8-7) )/15, 0) + 1) | AA8: =B8 -> Infernape | AC8: Raging Fury | AD8: =VLOOKUP(AC8,moves!A:B,2,FALSE) -> fire | AE8: =VLOOKUP(AC8,moves!A:D,4,FALSE) -> 5 | AF8: =VLOOKUP(AC8,moves!A:F,5,FALSE) -> 0 | AG8: 0 | AH8: 0 | AI8: {=_xlfn.IFS(AG8=1, "starter", AH8=1, "legendary",T8< 13, "weak",T8< 17, "moderate", TRUE, "strong")} -> strong | AK8: 3 | AL8: 0 | AM8: 1
A9: 392-n | B9: Infernape | C9: fire | D9: fighting | E9: 76 | F9: 104 | G9: 71 | H9: 104 | I9: 71 | J9: 108 | K9: Flame Pokémon | M9: Noble | N9: =(0.4*J9 + 0.5*MAX(F9,H9) + 0.1*MIN(F9,H9)) / 10 -> 10.56 | O9: =(0.4*E9 + 0.3*G9 + 0.3*I9) / 10 -> 7.3 | P9: 2 | Q9: 2 | R9: =ROUND(N9,0)+P9 -> 13 | S9: =ROUND(O9,0)+Q9 -> 9 | T9: =SUM(ROUND(R9,0),ROUND(S9,0)) -> 22 | U9: =C9 -> fire | V9: =IF(D9 = 0, "", D9) -> fighting | W9: rock | X9: flying | Z9: =IF(ISBLANK(Y9), "", ROUND(( (T11-6)*(T11-7) - (T9-6)*(T9-7) )/15, 0) + 1) | AA9: =B9 -> Infernape | AB9: Noble Form | AC9: Raging Fury | AD9: =VLOOKUP(AC9,moves!A:B,2,FALSE) -> fire | AE9: =VLOOKUP(AC9,moves!A:D,4,FALSE) -> 5 | AF9: =VLOOKUP(AC9,moves!A:F,5,FALSE) -> 0 | AG9: 0 | AH9: 1 | AI9: {=_xlfn.IFS(AG9=1, "starter", AH9=1, "legendary",T9< 13, "weak",T9< 17, "moderate", TRUE, "strong")} -> legendary | AK9: 3 | AL9: 0 | AM9: 2
A10: 393 | B10: Piplup | C10: water | E10: 53 | F10: 51 | G10: 53 | H10: 61 | I10: 56 | J10: 40 | K10: Penguin Pokémon | L10: Ocean | M10: Cold | N10: =(0.4*J10 + 0.5*MAX(F10,H10) + 0.1*MIN(F10,H10)) / 10 -> 5.16 | O10: =(0.4*E10 + 0.3*G10 + 0.3*I10) / 10 -> 5.39 | P10: 0 | Q10: 0 | R10: =ROUND(N10,0)+P10 -> 5 | S10: =ROUND(O10,0)+Q10 -> 5 | T10: =SUM(ROUND(R10,0),ROUND(S10,0)) -> 10 | U10: =C10 -> water | V10: steel | W10: flying | X10: ice | Y10: =B11 -> Prinplup | Z10: =IF(ISBLANK(Y10), "", ROUND(( (T11-6)*(T11-7) - (T10-6)*(T10-7) )/15, 0) + 1) -> 4 | AA10: =B10 -> Piplup | AC10: Bubble Beam | AD10: =VLOOKUP(AC10,moves!A:B,2,FALSE) -> water | AE10: =VLOOKUP(AC10,moves!A:D,4,FALSE) -> 3 | AF10: =VLOOKUP(AC10,moves!A:F,5,FALSE) -> 0 | AG10: 1 | AH10: 0 | AI10: {=_xlfn.IFS(AG10=1, "starter", AH10=1, "legendary",T10< 13, "weak",T10< 17, "moderate", TRUE, "strong")} -> starter | AK10: 1 | AL10: 0 | AM10: 0
A11: 394 | B11: Prinplup | C11: water | E11: 64 | F11: 66 | G11: 68 | H11: 81 | I11: 76 | J11: 50 | K11: Penguin Pokémon | L11: Ocean | M11: Cold | N11: =(0.4*J11 + 0.5*MAX(F11,H11) + 0.1*MIN(F11,H11)) / 10 -> 6.71 | O11: =(0.4*E11 + 0.3*G11 + 0.3*I11) / 10 -> 6.88 | P11: 0 | Q11: 0 | R11: =ROUND(N11,0)+P11 -> 7 | S11: =ROUND(O11,0)+Q11 -> 7 | T11: =SUM(ROUND(R11,0),ROUND(S11,0)) -> 14 | U11: =C11 -> water | V11: steel | W11: flying | X11: ice | Y11: =B12 -> Empoleon | Z11: =IF(ISBLANK(Y11), "", ROUND(( (T12-6)*(T12-7) - (T11-6)*(T11-7) )/15, 0) + 1) -> 6 | AA11: =B11 -> Prinplup | AC11: Metal Claw | AD11: =VLOOKUP(AC11,moves!A:B,2,FALSE) -> steel | AE11: =VLOOKUP(AC11,moves!A:D,4,FALSE) -> 3 | AF11: =VLOOKUP(AC11,moves!A:F,5,FALSE) -> 0 | AG11: 0 | AH11: 0 | AI11: {=_xlfn.IFS(AG11=1, "starter", AH11=1, "legendary",T11< 13, "weak",T11< 17, "moderate", TRUE, "strong")} -> moderate | AK11: 2 | AL11: 0 | AM11: 0
A12: 395 | B12: Empoleon | C12: water | D12: steel | E12: 84 | F12: 86 | G12: 88 | H12: 111 | I12: 101 | J12: 60 | K12: Emperor Pokémon | L12: Ocean | M12: Cold | N12: =(0.4*J12 + 0.5*MAX(F12,H12) + 0.1*MIN(F12,H12)) / 10 -> 8.81 | O12: =(0.4*E12 + 0.3*G12 + 0.3*I12) / 10 -> 9.03 | P12: 0 | Q12: 0 | R12: =ROUND(N12,0)+P12 -> 9 | S12: =ROUND(O12,0)+Q12 -> 9 | T12: =SUM(ROUND(R12,0),ROUND(S12,0)) -> 18 | U12: =C12 -> water | V12: steel | W12: flying | X12: ice | Z12: =IF(ISBLANK(Y12), "", ROUND(( (T14-6)*(T14-7) - (T12-6)*(T12-7) )/15, 0) + 1) | AA12: =B12 -> Empoleon | AC12: Wave Crash | AD12: =VLOOKUP(AC12,moves!A:B,2,FALSE) -> water | AE12: =VLOOKUP(AC12,moves!A:D,4,FALSE) -> 5 | AF12: =VLOOKUP(AC12,moves!A:F,5,FALSE) -> 0 | AG12: 0 | AH12: 0 | AI12: {=_xlfn.IFS(AG12=1, "starter", AH12=1, "legendary",T12< 13, "weak",T12< 17, "moderate", TRUE, "strong")} -> strong | AK12: 3 | AL12: 0 | AM12: 1
A13: 395-n | B13: Empoleon | C13: water | D13: steel | E13: 84 | F13: 86 | G13: 88 | H13: 111 | I13: 101 | J13: 60 | K13: Emperor Pokémon | M13: Noble | N13: =(0.4*J13 + 0.5*MAX(F13,H13) + 0.1*MIN(F13,H13)) / 10 -> 8.81 | O13: =(0.4*E13 + 0.3*G13 + 0.3*I13) / 10 -> 9.03 | P13: 2 | Q13: 2 | R13: =ROUND(N13,0)+P13 -> 11 | S13: =ROUND(O13,0)+Q13 -> 11 | T13: =SUM(ROUND(R13,0),ROUND(S13,0)) -> 22 | U13: =C13 -> water | V13: steel | W13: flying | X13: ice | Z13: =IF(ISBLANK(Y13), "", ROUND(( (T15-6)*(T15-7) - (T13-6)*(T13-7) )/15, 0) + 1) | AA13: =B13 -> Empoleon | AB13: Noble Form | AC13: Wave Crash | AD13: =VLOOKUP(AC13,moves!A:B,2,FALSE) -> water | AE13: =VLOOKUP(AC13,moves!A:D,4,FALSE) -> 5 | AF13: =VLOOKUP(AC13,moves!A:F,5,FALSE) -> 0 | AG13: 0 | AH13: 1 | AI13: {=_xlfn.IFS(AG13=1, "starter", AH13=1, "legendary",T13< 13, "weak",T13< 17, "moderate", TRUE, "strong")} -> legendary | AK13: 3 | AL13: 0 | AM13: 2
A14: 396 | B14: Starly | C14: normal | D14: flying | E14: 40 | F14: 55 | G14: 30 | H14: 30 | I14: 30 | J14: 60 | K14: Starling Pokémon | L14: Mountain | M14: Temperate | N14: =(0.4*J14 + 0.5*MAX(F14,H14) + 0.1*MIN(F14,H14)) / 10 -> 5.45 | O14: =(0.4*E14 + 0.3*G14 + 0.3*I14) / 10 -> 3.4 | P14: 1 | Q14: 1 | R14: =ROUND(N14,0)+P14 -> 6 | S14: =ROUND(O14,0)+Q14 -> 4 | T14: =SUM(ROUND(R14,0),ROUND(S14,0)) -> 10 | U14: =C14 -> normal | V14: =IF(D14 = 0, "", D14) -> flying | W14: fighting | X14: steel | Y14: =B15 -> Staravia | Z14: =IF(ISBLANK(Y14), "", ROUND(( (T15-6)*(T15-7) - (T14-6)*(T14-7) )/15, 0) + 1) -> 3 | AA14: =B14 -> Starly | AC14: Wing Attack | AD14: =VLOOKUP(AC14,moves!A:B,2,FALSE) -> flying | AE14: =VLOOKUP(AC14,moves!A:D,4,FALSE) -> 3 | AF14: =VLOOKUP(AC14,moves!A:F,5,FALSE) -> 0 | AG14: 1 | AH14: 0 | AI14: {=_xlfn.IFS(AG14=1, "starter", AH14=1, "legendary",T14< 13, "weak",T14< 17, "moderate", TRUE, "strong")} -> starter | AK14: 1 | AL14: 0 | AM14: 0
A15: 397 | B15: Staravia | C15: normal | D15: flying | E15: 55 | F15: 75 | G15: 50 | H15: 40 | I15: 40 | J15: 80 | K15: Starling Pokémon | L15: Mountain | M15: Temperate | N15: =(0.4*J15 + 0.5*MAX(F15,H15) + 0.1*MIN(F15,H15)) / 10 -> 7.35 | O15: =(0.4*E15 + 0.3*G15 + 0.3*I15) / 10 -> 4.9 | P15: 0 | Q15: 1 | R15: =ROUND(N15,0)+P15 -> 7 | S15: =ROUND(O15,0)+Q15 -> 6 | T15: =SUM(ROUND(R15,0),ROUND(S15,0)) -> 13 | U15: =C15 -> normal | V15: =IF(D15 = 0, "", D15) -> flying | W15: fighting | X15: steel | Y15: =B16 -> Staraptor | Z15: =IF(ISBLANK(Y15), "", ROUND(( (T16-6)*(T16-7) - (T15-6)*(T15-7) )/15, 0) + 1) -> 7 | AA15: =B15 -> Staravia | AC15: Steel Wing | AD15: =VLOOKUP(AC15,moves!A:B,2,FALSE) -> steel | AE15: =VLOOKUP(AC15,moves!A:D,4,FALSE) -> 3 | AF15: =VLOOKUP(AC15,moves!A:F,5,FALSE) -> 0 | AG15: 0 | AH15: 0 | AI15: {=_xlfn.IFS(AG15=1, "starter", AH15=1, "legendary",T15< 13, "weak",T15< 17, "moderate", TRUE, "strong")} -> moderate | AK15: 2 | AL15: 0 | AM15: 0
A16: 398 | B16: Staraptor | C16: normal | D16: flying | E16: 85 | F16: 120 | G16: 70 | H16: 50 | I16: 60 | J16: 100 | K16: Predator Pokémon | L16: Mountain | M16: Temperate | N16: =(0.4*J16 + 0.5*MAX(F16,H16) + 0.1*MIN(F16,H16)) / 10 -> 10.5 | O16: =(0.4*E16 + 0.3*G16 + 0.3*I16) / 10 -> 7.3 | P16: 0 | Q16: 0 | R16: =ROUND(N16,0)+P16 -> 11 | S16: =ROUND(O16,0)+Q16 -> 7 | T16: =SUM(ROUND(R16,0),ROUND(S16,0)) -> 18 | U16: =C16 -> normal | V16: =IF(D16 = 0, "", D16) -> flying | W16: fighting | X16: steel | Z16: =IF(ISBLANK(Y16), "", ROUND(( (T18-6)*(T18-7) - (T16-6)*(T16-7) )/15, 0) + 1) | AA16: =B16 -> Staraptor | AC16: Close Combat | AD16: =VLOOKUP(AC16,moves!A:B,2,FALSE) -> fighting | AE16: =VLOOKUP(AC16,moves!A:D,4,FALSE) -> 5 | AF16: =VLOOKUP(AC16,moves!A:F,5,FALSE) -> 0 | AG16: 0 | AH16: 0 | AI16: {=_xlfn.IFS(AG16=1, "starter", AH16=1, "legendary",T16< 13, "weak",T16< 17, "moderate", TRUE, "strong")} -> strong | AK16: 3 | AL16: 0 | AM16: 1
A17: 398-n | B17: Staraptor | C17: normal | D17: flying | E17: 85 | F17: 120 | G17: 70 | H17: 50 | I17: 60 | J17: 100 | K17: Predator Pokémon | M17: Noble | N17: =(0.4*J17 + 0.5*MAX(F17,H17) + 0.1*MIN(F17,H17)) / 10 -> 10.5 | O17: =(0.4*E17 + 0.3*G17 + 0.3*I17) / 10 -> 7.3 | P17: 2 | Q17: 2 | R17: =ROUND(N17,0)+P17 -> 13 | S17: =ROUND(O17,0)+Q17 -> 9 | T17: =SUM(ROUND(R17,0),ROUND(S17,0)) -> 22 | U17: =C17 -> normal | V17: =IF(D17 = 0, "", D17) -> flying | W17: fighting | X17: steel | Z17: =IF(ISBLANK(Y17), "", ROUND(( (T19-6)*(T19-7) - (T17-6)*(T17-7) )/15, 0) + 1) | AA17: =B17 -> Staraptor | AB17: Noble Form | AC17: Close Combat | AD17: =VLOOKUP(AC17,moves!A:B,2,FALSE) -> fighting | AE17: =VLOOKUP(AC17,moves!A:D,4,FALSE) -> 5 | AF17: =VLOOKUP(AC17,moves!A:F,5,FALSE) -> 0 | AG17: 0 | AH17: 1 | AI17: {=_xlfn.IFS(AG17=1, "starter", AH17=1, "legendary",T17< 13, "weak",T17< 17, "moderate", TRUE, "strong")} -> legendary | AK17: 3 | AL17: 0 | AM17: 2
A18: 399 | B18: Bidoof | C18: normal | E18: 59 | F18: 45 | G18: 40 | H18: 35 | I18: 40 | J18: 31 | K18: Plump Mouse Pokémon | L18: Plains | M18: Temperate | N18: =(0.4*J18 + 0.5*MAX(F18,H18) + 0.1*MIN(F18,H18)) / 10 -> 3.84 | O18: =(0.4*E18 + 0.3*G18 + 0.3*I18) / 10 -> 4.76 | P18: 0 | Q18: 0 | R18: =ROUND(N18,0)+P18 -> 4 | S18: =ROUND(O18,0)+Q18 -> 5 | T18: =SUM(ROUND(R18,0),ROUND(S18,0)) -> 9 | U18: =C18 -> normal | V18: water | W18: fighting | X18: electric | Y18: =B19 -> Bibarel | Z18: =IF(ISBLANK(Y18), "", ROUND(( (T19-6)*(T19-7) - (T18-6)*(T18-7) )/15, 0) + 1) -> 5 | AA18: =B18 -> Bidoof | AC18: Tackle | AD18: =VLOOKUP(AC18,moves!A:B,2,FALSE) -> normal | AE18: =VLOOKUP(AC18,moves!A:D,4,FALSE) -> 2 | AF18: =VLOOKUP(AC18,moves!A:F,5,FALSE) -> 0 | AG18: 0 | AH18: 0 | AI18: {=_xlfn.IFS(AG18=1, "starter", AH18=1, "legendary",T18< 13, "weak",T18< 17, "moderate", TRUE, "strong")} -> weak | AK18: 1 | AL18: 0 | AM18: 0
A19: 400 | B19: Bibarel | C19: normal | D19: water | E19: 79 | F19: 85 | G19: 60 | H19: 55 | I19: 60 | J19: 71 | K19: Beaver Pokémon | L19: Plains | M19: Temperate | N19: =(0.4*J19 + 0.5*MAX(F19,H19) + 0.1*MIN(F19,H19)) / 10 -> 7.64 | O19: =(0.4*E19 + 0.3*G19 + 0.3*I19) / 10 -> 6.76 | P19: 0 | Q19: 0 | R19: =ROUND(N19,0)+P19 -> 8 | S19: =ROUND(O19,0)+Q19 -> 7 | T19: =SUM(ROUND(R19,0),ROUND(S19,0)) -> 15 | U19: =C19 -> normal | V19: =IF(D19 = 0, "", D19) -> water | W19: fighting | X19: electric | Z19: =IF(ISBLANK(Y19), "", ROUND(( (T20-6)*(T20-7) - (T19-6)*(T19-7) )/15, 0) + 1) | AA19: =B19 -> Bibarel | AC19: Surf | AD19: =VLOOKUP(AC19,moves!A:B,2,FALSE) -> water | AE19: =VLOOKUP(AC19,moves!A:D,4,FALSE) -> 4 | AF19: =VLOOKUP(AC19,moves!A:F,5,FALSE) -> 0 | AG19: 0 | AH19: 0 | AI19: {=_xlfn.IFS(AG19=1, "starter", AH19=1, "legendary",T19< 13, "weak",T19< 17, "moderate", TRUE, "strong")} -> moderate | AK19: 2 | AL19: 0 | AM19: 0
A20: 401 | B20: Kricketot | C20: bug | E20: 37 | F20: 25 | G20: 41 | H20: 25 | I20: 41 | J20: 25 | K20: Cricket Pokémon | L20: Plains | M20: Warm | N20: =(0.4*J20 + 0.5*MAX(F20,H20) + 0.1*MIN(F20,H20)) / 10 -> 2.5 | O20: =(0.4*E20 + 0.3*G20 + 0.3*I20) / 10 -> 3.94 | P20: 0 | Q20: 0 | R20: =ROUND(N20,0)+P20 -> 3 | S20: =ROUND(O20,0)+Q20 -> 4 | T20: =SUM(ROUND(R20,0),ROUND(S20,0)) -> 7 | U20: =C20 -> bug | V20: normal | W20: dark | X20: grass | Y20: =B21 -> Kricketune | Z20: =IF(ISBLANK(Y20), "", ROUND(( (T21-6)*(T21-7) - (T20-6)*(T20-7) )/15, 0) + 1) -> 4 | AA20: =B20 -> Kricketot | AC20: Struggle Bug | AD20: =VLOOKUP(AC20,moves!A:B,2,FALSE) -> bug | AE20: =VLOOKUP(AC20,moves!A:D,4,FALSE) -> 2 | AF20: =VLOOKUP(AC20,moves!A:F,5,FALSE) -> 0 | AG20: 0 | AH20: 0 | AI20: {=_xlfn.IFS(AG20=1, "starter", AH20=1, "legendary",T20< 13, "weak",T20< 17, "moderate", TRUE, "strong")} -> weak | AK20: 1 | AL20: 0 | AM20: 0
A21: 402 | B21: Kricketune | C21: bug | E21: 77 | F21: 85 | G21: 51 | H21: 55 | I21: 51 | J21: 65 | K21: Cricket Pokémon | L21: Plains | M21: Warm | N21: =(0.4*J21 + 0.5*MAX(F21,H21) + 0.1*MIN(F21,H21)) / 10 -> 7.4 | O21: =(0.4*E21 + 0.3*G21 + 0.3*I21) / 10 -> 6.14 | P21: 0 | Q21: 0 | R21: =ROUND(N21,0)+P21 -> 7 | S21: =ROUND(O21,0)+Q21 -> 6 | T21: =SUM(ROUND(R21,0),ROUND(S21,0)) -> 13 | U21: =C21 -> bug | V21: normal | W21: dark | X21: grass | Z21: =IF(ISBLANK(Y21), "", ROUND(( (T22-6)*(T22-7) - (T21-6)*(T21-7) )/15, 0) + 1) | AA21: =B21 -> Kricketune | AC21: Perish Song | AD21: =VLOOKUP(AC21,moves!A:B,2,FALSE) -> normal | AE21: =VLOOKUP(AC21,moves!A:D,4,FALSE) -> 1 | AF21: =VLOOKUP(AC21,moves!A:F,5,FALSE) -> 0 | AG21: 0 | AH21: 0 | AI21: {=_xlfn.IFS(AG21=1, "starter", AH21=1, "legendary",T21< 13, "weak",T21< 17, "moderate", TRUE, "strong")} -> moderate | AK21: 2 | AL21: 0 | AM21: 0
A22: 403 | B22: Shinx | C22: electric | E22: 45 | F22: 65 | G22: 34 | H22: 40 | I22: 34 | J22: 45 | K22: Flash Pokémon | L22: Plains | M22: Warm | N22: =(0.4*J22 + 0.5*MAX(F22,H22) + 0.1*MIN(F22,H22)) / 10 -> 5.45 | O22: =(0.4*E22 + 0.3*G22 + 0.3*I22) / 10 -> 3.84 | P22: 1 | Q22: 0 | R22: =ROUND(N22,0)+P22 -> 6 | S22: =ROUND(O22,0)+Q22 -> 4 | T22: =SUM(ROUND(R22,0),ROUND(S22,0)) -> 10 | U22: =C22 -> electric | V22: dark | W22: normal | X22: fighting | Y22: =B23 -> Luxio | Z22: =IF(ISBLANK(Y22), "", ROUND(( (T23-6)*(T23-7) - (T22-6)*(T22-7) )/15, 0) + 1) -> 3 | AA22: =B22 -> Shinx | AC22: Volt Switch | AD22: =VLOOKUP(AC22,moves!A:B,2,FALSE) -> electric | AE22: =VLOOKUP(AC22,moves!A:D,4,FALSE) -> 3 | AF22: =VLOOKUP(AC22,moves!A:F,5,FALSE) -> switch | AG22: 1 | AH22: 0 | AI22: {=_xlfn.IFS(AG22=1, "starter", AH22=1, "legendary",T22< 13, "weak",T22< 17, "moderate", TRUE, "strong")} -> starter | AK22: 1 | AL22: 0 | AM22: 0
A23: 404 | B23: Luxio | C23: electric | E23: 60 | F23: 85 | G23: 49 | H23: 60 | I23: 49 | J23: 60 | K23: Spark Pokémon | L23: Plains | M23: Warm | N23: =(0.4*J23 + 0.5*MAX(F23,H23) + 0.1*MIN(F23,H23)) / 10 -> 7.25 | O23: =(0.4*E23 + 0.3*G23 + 0.3*I23) / 10 -> 5.34 | P23: 0 | Q23: 1 | R23: =ROUND(N23,0)+P23 -> 7 | S23: =ROUND(O23,0)+Q23 -> 6 | T23: =SUM(ROUND(R23,0),ROUND(S23,0)) -> 13 | U23: =C23 -> electric | V23: dark | W23: normal | X23: fighting | Y23: =B24 -> Luxray | Z23: =IF(ISBLANK(Y23), "", ROUND(( (T24-6)*(T24-7) - (T23-6)*(T23-7) )/15, 0) + 1) -> 7 | AA23: =B23 -> Luxio | AC23: Bite | AD23: =VLOOKUP(AC23,moves!A:B,2,FALSE) -> dark | AE23: =VLOOKUP(AC23,moves!A:D,4,FALSE) -> 3 | AF23: =VLOOKUP(AC23,moves!A:F,5,FALSE) -> 0 | AG23: 0 | AH23: 0 | AI23: {=_xlfn.IFS(AG23=1, "starter", AH23=1, "legendary",T23< 13, "weak",T23< 17, "moderate", TRUE, "strong")} -> moderate | AK23: 2 | AL23: 0 | AM23: 0
A24: 405 | B24: Luxray | C24: electric | E24: 80 | F24: 120 | G24: 79 | H24: 95 | I24: 79 | J24: 70 | K24: Gleam Eyes Pokémon | L24: Plains | M24: Warm | N24: =(0.4*J24 + 0.5*MAX(F24,H24) + 0.1*MIN(F24,H24)) / 10 -> 9.75 | O24: =(0.4*E24 + 0.3*G24 + 0.3*I24) / 10 -> 7.94 | P24: 0 | Q24: 0 | R24: =ROUND(N24,0)+P24 -> 10 | S24: =ROUND(O24,0)+Q24 -> 8 | T24: =SUM(ROUND(R24,0),ROUND(S24,0)) -> 18 | U24: =C24 -> electric | V24: dark | W24: normal | X24: fighting | Z24: =IF(ISBLANK(Y24), "", ROUND(( (T26-6)*(T26-7) - (T24-6)*(T24-7) )/15, 0) + 1) | AA24: =B24 -> Luxray | AC24: Wild Charge | AD24: =VLOOKUP(AC24,moves!A:B,2,FALSE) -> electric | AE24: =VLOOKUP(AC24,moves!A:D,4,FALSE) -> 4 | AF24: =VLOOKUP(AC24,moves!A:F,5,FALSE) -> 0 | AG24: 0 | AH24: 0 | AI24: {=_xlfn.IFS(AG24=1, "starter", AH24=1, "legendary",T24< 13, "weak",T24< 17, "moderate", TRUE, "strong")} -> strong | AK24: 3 | AL24: 0 | AM24: 1
A25: 405-n | B25: Luxray | C25: electric | E25: 80 | F25: 120 | G25: 79 | H25: 95 | I25: 79 | J25: 70 | K25: Gleam Eyes Pokémon | M25: Noble | N25: =(0.4*J25 + 0.5*MAX(F25,H25) + 0.1*MIN(F25,H25)) / 10 -> 9.75 | O25: =(0.4*E25 + 0.3*G25 + 0.3*I25) / 10 -> 7.94 | P25: 2 | Q25: 2 | R25: =ROUND(N25,0)+P25 -> 12 | S25: =ROUND(O25,0)+Q25 -> 10 | T25: =SUM(ROUND(R25,0),ROUND(S25,0)) -> 22 | U25: =C25 -> electric | V25: dark | W25: normal | X25: fighting | Z25: =IF(ISBLANK(Y25), "", ROUND(( (T27-6)*(T27-7) - (T25-6)*(T25-7) )/15, 0) + 1) | AA25: =B25 -> Luxray | AB25: Noble Form | AC25: Wild Charge | AD25: =VLOOKUP(AC25,moves!A:B,2,FALSE) -> electric | AE25: =VLOOKUP(AC25,moves!A:D,4,FALSE) -> 4 | AF25: =VLOOKUP(AC25,moves!A:F,5,FALSE) -> 0 | AG25: 0 | AH25: 1 | AI25: {=_xlfn.IFS(AG25=1, "starter", AH25=1, "legendary",T25< 13, "weak",T25< 17, "moderate", TRUE, "strong")} -> legendary | AK25: 3 | AL25: 0 | AM25: 2
A26: 406 | B26: Budew | C26: grass | D26: poison | E26: 40 | F26: 30 | G26: 35 | H26: 50 | I26: 70 | J26: 55 | K26: Bud Pokémon | L26: Plains | M26: Warm | N26: =(0.4*J26 + 0.5*MAX(F26,H26) + 0.1*MIN(F26,H26)) / 10 -> 5 | O26: =(0.4*E26 + 0.3*G26 + 0.3*I26) / 10 -> 4.75 | P26: 0 | Q26: 0 | R26: =ROUND(N26,0)+P26 -> 5 | S26: =ROUND(O26,0)+Q26 -> 5 | T26: =SUM(ROUND(R26,0),ROUND(S26,0)) -> 10 | U26: =C26 -> grass | V26: =IF(D26 = 0, "", D26) -> poison | W26: normal | X26: fairy | Y26: =B27 -> Roselia | Z26: =IF(ISBLANK(Y26), "", ROUND(( (T27-6)*(T27-7) - (T26-6)*(T26-7) )/15, 0) + 1) -> 4 | AA26: =B26 -> Budew | AC26: Grass Whistle | AD26: =VLOOKUP(AC26,moves!A:B,2,FALSE) -> grass | AE26: =VLOOKUP(AC26,moves!A:D,4,FALSE) -> 1 | AF26: =VLOOKUP(AC26,moves!A:F,5,FALSE) -> agile | AG26: 1 | AH26: 0 | AI26: {=_xlfn.IFS(AG26=1, "starter", AH26=1, "legendary",T26< 13, "weak",T26< 17, "moderate", TRUE, "strong")} -> starter | AK26: 1 | AL26: 0 | AM26: 0
A27: 315 | B27: Roselia | C27: grass | D27: poison | E27: 50 | F27: 60 | G27: 45 | H27: 100 | I27: 80 | J27: 65 | K27: Thorn Pokémon | L27: Plains | M27: Warm | N27: =(0.4*J27 + 0.5*MAX(F27,H27) + 0.1*MIN(F27,H27)) / 10 -> 8.2 | O27: =(0.4*E27 + 0.3*G27 + 0.3*I27) / 10 -> 5.75 | P27: 0 | Q27: 0 | R27: =ROUND(N27,0)+P27 -> 8 | S27: =ROUND(O27,0)+Q27 -> 6 | T27: =SUM(ROUND(R27,0),ROUND(S27,0)) -> 14 | U27: =C27 -> grass | V27: =IF(D27 = 0, "", D27) -> poison | W27: normal | X27: fairy | Y27: =B28 -> Roserade | Z27: =IF(ISBLANK(Y27), "", ROUND(( (T28-6)*(T28-7) - (T27-6)*(T27-7) )/15, 0) + 1) -> 8 | AA27: =B27 -> Roselia | AC27: Venoshock | AD27: =VLOOKUP(AC27,moves!A:B,2,FALSE) -> poison | AE27: =VLOOKUP(AC27,moves!A:D,4,FALSE) -> 3 | AF27: =VLOOKUP(AC27,moves!A:F,5,FALSE) -> 0 | AG27: 0 | AH27: 0 | AI27: {=_xlfn.IFS(AG27=1, "starter", AH27=1, "legendary",T27< 13, "weak",T27< 17, "moderate", TRUE, "strong")} -> moderate | AK27: 2 | AL27: 0 | AM27: 0
A28: 407 | B28: Roserade | C28: grass | D28: poison | E28: 60 | F28: 70 | G28: 65 | H28: 125 | I28: 105 | J28: 90 | K28: Bouquet Pokémon | L28: Plains | M28: Warm | N28: =(0.4*J28 + 0.5*MAX(F28,H28) + 0.1*MIN(F28,H28)) / 10 -> 10.55 | O28: =(0.4*E28 + 0.3*G28 + 0.3*I28) / 10 -> 7.5 | P28: 0 | Q28: 0 | R28: =ROUND(N28,0)+P28 -> 11 | S28: =ROUND(O28,0)+Q28 -> 8 | T28: =SUM(ROUND(R28,0),ROUND(S28,0)) -> 19 | U28: =C28 -> grass | V28: =IF(D28 = 0, "", D28) -> poison | W28: normal | X28: fairy | Z28: =IF(ISBLANK(Y28), "", ROUND(( (T30-6)*(T30-7) - (T28-6)*(T28-7) )/15, 0) + 1) | AA28: =B28 -> Roserade | AC28: Petal Dance | AD28: =VLOOKUP(AC28,moves!A:B,2,FALSE) -> grass | AE28: =VLOOKUP(AC28,moves!A:D,4,FALSE) -> 5 | AF28: =VLOOKUP(AC28,moves!A:F,5,FALSE) -> 0 | AG28: 0 | AH28: 0 | AI28: {=_xlfn.IFS(AG28=1, "starter", AH28=1, "legendary",T28< 13, "weak",T28< 17, "moderate", TRUE, "strong")} -> strong | AK28: 3 | AL28: 0 | AM28: 1
A29: 407-n | B29: Roserade | C29: grass | D29: poison | E29: 60 | F29: 70 | G29: 65 | H29: 125 | I29: 105 | J29: 90 | K29: Bouquet Pokémon | M29: Noble | N29: =(0.4*J29 + 0.5*MAX(F29,H29) + 0.1*MIN(F29,H29)) / 10 -> 10.55 | O29: =(0.4*E29 + 0.3*G29 + 0.3*I29) / 10 -> 7.5 | P29: 2 | Q29: 2 | R29: =ROUND(N29,0)+P29 -> 13 | S29: =ROUND(O29,0)+Q29 -> 10 | T29: =SUM(ROUND(R29,0),ROUND(S29,0)) -> 23 | U29: =C29 -> grass | V29: =IF(D29 = 0, "", D29) -> poison | W29: normal | X29: fairy | Z29: =IF(ISBLANK(Y29), "", ROUND(( (T31-6)*(T31-7) - (T29-6)*(T29-7) )/15, 0) + 1) | AA29: =B29 -> Roserade | AB29: Noble Form | AC29: Petal Dance | AD29: =VLOOKUP(AC29,moves!A:B,2,FALSE) -> grass | AE29: =VLOOKUP(AC29,moves!A:D,4,FALSE) -> 5 | AF29: =VLOOKUP(AC29,moves!A:F,5,FALSE) -> 0 | AG29: 0 | AH29: 1 | AI29: {=_xlfn.IFS(AG29=1, "starter", AH29=1, "legendary",T29< 13, "weak",T29< 17, "moderate", TRUE, "strong")} -> legendary | AK29: 3 | AL29: 0 | AM29: 2
A30: 408 | B30: Cranidos | C30: rock | E30: 67 | F30: 125 | G30: 40 | H30: 30 | I30: 30 | J30: 58 | K30: Head Butt Pokémon | L30: Plains | M30: Temperate | N30: =(0.4*J30 + 0.5*MAX(F30,H30) + 0.1*MIN(F30,H30)) / 10 -> 8.87 | O30: =(0.4*E30 + 0.3*G30 + 0.3*I30) / 10 -> 4.78 | P30: 0 | Q30: 0 | R30: =ROUND(N30,0)+P30 -> 9 | S30: =ROUND(O30,0)+Q30 -> 5 | T30: =SUM(ROUND(R30,0),ROUND(S30,0)) -> 14 | U30: =C30 -> rock | V30: normal | W30: dark | X30: ground | Y30: =B31 -> Rampardos | Z30: =IF(ISBLANK(Y30), "", ROUND(( (T31-6)*(T31-7) - (T30-6)*(T30-7) )/15, 0) + 1) -> 6 | AA30: =B30 -> Cranidos | AC30: Headbutt | AD30: =VLOOKUP(AC30,moves!A:B,2,FALSE) -> normal | AE30: =VLOOKUP(AC30,moves!A:D,4,FALSE) -> 3 | AF30: =VLOOKUP(AC30,moves!A:F,5,FALSE) -> 0 | AG30: 0 | AH30: 0 | AI30: {=_xlfn.IFS(AG30=1, "starter", AH30=1, "legendary",T30< 13, "weak",T30< 17, "moderate", TRUE, "strong")} -> moderate | AK30: 1 | AL30: 0 | AM30: 0
A31: 409 | B31: Rampardos | C31: rock | E31: 97 | F31: 165 | G31: 60 | H31: 65 | I31: 50 | J31: 58 | K31: Head Butt Pokémon | L31: Plains | M31: Temperate | N31: =(0.4*J31 + 0.5*MAX(F31,H31) + 0.1*MIN(F31,H31)) / 10 -> 11.22 | O31: =(0.4*E31 + 0.3*G31 + 0.3*I31) / 10 -> 7.18 | P31: 0 | Q31: 0 | R31: =ROUND(N31,0)+P31 -> 11 | S31: =ROUND(O31,0)+Q31 -> 7 | T31: =SUM(ROUND(R31,0),ROUND(S31,0)) -> 18 | U31: =C31 -> rock | V31: normal | W31: dark | X31: ground | Z31: =IF(ISBLANK(Y31), "", ROUND(( (T32-6)*(T32-7) - (T31-6)*(T31-7) )/15, 0) + 1) | AA31: =B31 -> Rampardos | AC31: Head Smash | AD31: =VLOOKUP(AC31,moves!A:B,2,FALSE) -> rock | AE31: =VLOOKUP(AC31,moves!A:D,4,FALSE) -> 8 | AF31: =VLOOKUP(AC31,moves!A:F,5,FALSE) -> decisive | AG31: 0 | AH31: 0 | AI31: {=_xlfn.IFS(AG31=1, "starter", AH31=1, "legendary",T31< 13, "weak",T31< 17, "moderate", TRUE, "strong")} -> strong | AK31: 2 | AL31: 0 | AM31: 0
A32: 410 | B32: Shieldon | C32: rock | D32: steel | E32: 30 | F32: 42 | G32: 118 | H32: 42 | I32: 88 | J32: 30 | K32: Shield Pokémon | L32: Plains | M32: Temperate | N32: =(0.4*J32 + 0.5*MAX(F32,H32) + 0.1*MIN(F32,H32)) / 10 -> 3.72 | O32: =(0.4*E32 + 0.3*G32 + 0.3*I32) / 10 -> 7.38 | P32: 0 | Q32: 0 | R32: =ROUND(N32,0)+P32 -> 4 | S32: =ROUND(O32,0)+Q32 -> 7 | T32: =SUM(ROUND(R32,0),ROUND(S32,0)) -> 11 | U32: =C32 -> rock | V32: steel | W32: normal | X32: ice | Y32: =B33 -> Bastiodon | Z32: =IF(ISBLANK(Y32), "", ROUND(( (T33-6)*(T33-7) - (T32-6)*(T32-7) )/15, 0) + 1) -> 6 | AA32: =B32 -> Shieldon | AC32: Ancient Power | AD32: =VLOOKUP(AC32,moves!A:B,2,FALSE) -> rock | AE32: =VLOOKUP(AC32,moves!A:D,4,FALSE) -> 2 | AF32: =VLOOKUP(AC32,moves!A:F,5,FALSE) -> boost | AG32: 0 | AH32: 0 | AI32: {=_xlfn.IFS(AG32=1, "starter", AH32=1, "legendary",T32< 13, "weak",T32< 17, "moderate", TRUE, "strong")} -> weak | AK32: 1 | AL32: 0 | AM32: 0
A33: 411 | B33: Bastiodon | C33: rock | D33: steel | E33: 60 | F33: 52 | G33: 168 | H33: 47 | I33: 138 | J33: 30 | K33: Shield Pokémon | L33: Plains | M33: Temperate | N33: =(0.4*J33 + 0.5*MAX(F33,H33) + 0.1*MIN(F33,H33)) / 10 -> 4.27 | O33: =(0.4*E33 + 0.3*G33 + 0.3*I33) / 10 -> 11.58 | P33: 0 | Q33: 0 | R33: =ROUND(N33,0)+P33 -> 4 | S33: =ROUND(O33,0)+Q33 -> 12 | T33: =SUM(ROUND(R33,0),ROUND(S33,0)) -> 16 | U33: =C33 -> rock | V33: steel | W33: normal | X33: ice | Z33: =IF(ISBLANK(Y33), "", ROUND(( (T34-6)*(T34-7) - (T33-6)*(T33-7) )/15, 0) + 1) | AA33: =B33 -> Bastiodon | AC33: Heavy Slam | AD33: =VLOOKUP(AC33,moves!A:B,2,FALSE) -> steel | AE33: =VLOOKUP(AC33,moves!A:D,4,FALSE) -> ? | AF33: =VLOOKUP(AC33,moves!A:F,5,FALSE) -> 0 | AG33: 0 | AH33: 0 | AI33: {=_xlfn.IFS(AG33=1, "starter", AH33=1, "legendary",T33< 13, "weak",T33< 17, "moderate", TRUE, "strong")} -> moderate | AK33: 2 | AL33: 0 | AM33: 0
A34: 412-p | B34: Burmy | C34: bug | E34: 40 | F34: 29 | G34: 45 | H34: 29 | I34: 45 | J34: 36 | K34: Bagworm Pokémon | L34: Forest | M34: Temperate | N34: =(0.4*J34 + 0.5*MAX(F34,H34) + 0.1*MIN(F34,H34)) / 10 -> 3.18 | O34: =(0.4*E34 + 0.3*G34 + 0.3*I34) / 10 -> 4.3 | P34: 0 | Q34: 0 | R34: =ROUND(N34,0)+P34 -> 3 | S34: =ROUND(O34,0)+Q34 -> 4 | T34: =SUM(ROUND(R34,0),ROUND(S34,0)) -> 7 | U34: =C34 -> bug | V34: grass | W34: ground | X34: steel | Y34: Wormadam/Mothim | Z34: =IF(ISBLANK(Y34), "", ROUND(( (T35-6)*(T35-7) - (T34-6)*(T34-7) )/15, 0) + 1) -> 5 | AA34: =B34 -> Burmy | AC34: Bug Bite | AD34: =VLOOKUP(AC34,moves!A:B,2,FALSE) -> bug | AE34: =VLOOKUP(AC34,moves!A:D,4,FALSE) -> 3 | AF34: =VLOOKUP(AC34,moves!A:F,5,FALSE) -> 0 | AG34: 0 | AH34: 0 | AI34: {=_xlfn.IFS(AG34=1, "starter", AH34=1, "legendary",T34< 13, "weak",T34< 17, "moderate", TRUE, "strong")} -> weak | AK34: 1 | AL34: 0 | AM34: 0
A35: 413 | B35: Wormadam | C35: bug | D35: grass | E35: 60 | F35: 69 | G35: 95 | H35: 69 | I35: 95 | J35: 36 | K35: Bagworm Pokémon | L35: Forest | M35: Temperate | N35: =(0.4*J35 + 0.5*MAX(F35,H35) + 0.1*MIN(F35,H35)) / 10 -> 5.58 | O35: =(0.4*E35 + 0.3*G35 + 0.3*I35) / 10 -> 8.1 | P35: 0 | Q35: 0 | R35: =ROUND(N35,0)+P35 -> 6 | S35: =ROUND(O35,0)+Q35 -> 8 | T35: =SUM(ROUND(R35,0),ROUND(S35,0)) -> 14 | U35: =C35 -> bug | V35: grass | W35: ground | X35: steel | Z35: =IF(ISBLANK(Y35), "", ROUND(( (T38-6)*(T38-7) - (T35-6)*(T35-7) )/15, 0) + 1) | AA35: =B35 -> Wormadam | AB35: Plant Cloak Form | AC35: Adaptive Cloak | AD35: =VLOOKUP(AC35,moves!A:B,2,FALSE) -> typeless | AE35: =VLOOKUP(AC35,moves!A:D,4,FALSE) -> 4 | AF35: =VLOOKUP(AC35,moves!A:F,5,FALSE) -> transform | AG35: 0 | AH35: 0 | AI35: {=_xlfn.IFS(AG35=1, "starter", AH35=1, "legendary",T35< 13, "weak",T35< 17, "moderate", TRUE, "strong")} -> moderate | AK35: 2 | AL35: 0 | AM35: 1
A36: 413-c | B36: Wormadam | C36: bug | D36: ground | E36: 60 | F36: 69 | G36: 95 | H36: 69 | I36: 95 | J36: 36 | K36: Bagworm Pokémon | L36: Forest | M36: Temperate | N36: =(0.4*J36 + 0.5*MAX(F36,H36) + 0.1*MIN(F36,H36)) / 10 -> 5.58 | O36: =(0.4*E36 + 0.3*G36 + 0.3*I36) / 10 -> 8.1 | P36: 0 | Q36: 0 | R36: =ROUND(N36,0)+P36 -> 6 | S36: =ROUND(O36,0)+Q36 -> 8 | T36: =SUM(ROUND(R36,0),ROUND(S36,0)) -> 14 | U36: =C36 -> bug | V36: grass | W36: ground | X36: steel | Z36: =IF(ISBLANK(Y36), "", ROUND(( (T39-6)*(T39-7) - (T36-6)*(T36-7) )/15, 0) + 1) | AA36: Sandy Wormadam | AB36: Sandy Cloak Form | AC36: Adaptive Cloak | AD36: =VLOOKUP(AC36,moves!A:B,2,FALSE) -> typeless | AE36: =VLOOKUP(AC36,moves!A:D,4,FALSE) -> 4 | AF36: =VLOOKUP(AC36,moves!A:F,5,FALSE) -> transform | AG36: 0 | AH36: 0 | AI36: {=_xlfn.IFS(AG36=1, "starter", AH36=1, "legendary",T36< 13, "weak",T36< 17, "moderate", TRUE, "strong")} -> moderate | AK36: 2 | AL36: 0 | AM36: 2
A37: 413-t | B37: Wormadam | C37: bug | D37: steel | E37: 60 | F37: 69 | G37: 95 | H37: 69 | I37: 95 | J37: 36 | K37: Bagworm Pokémon | L37: Forest | M37: Temperate | N37: =(0.4*J37 + 0.5*MAX(F37,H37) + 0.1*MIN(F37,H37)) / 10 -> 5.58 | O37: =(0.4*E37 + 0.3*G37 + 0.3*I37) / 10 -> 8.1 | P37: 0 | Q37: 0 | R37: =ROUND(N37,0)+P37 -> 6 | S37: =ROUND(O37,0)+Q37 -> 8 | T37: =SUM(ROUND(R37,0),ROUND(S37,0)) -> 14 | U37: =C37 -> bug | V37: grass | W37: ground | X37: steel | Z37: =IF(ISBLANK(Y37), "", ROUND(( (T40-6)*(T40-7) - (T37-6)*(T37-7) )/15, 0) + 1) | AA37: Trash Wormadam | AB37: Trash Cloak Form | AC37: Adaptive Cloak | AD37: =VLOOKUP(AC37,moves!A:B,2,FALSE) -> typeless | AE37: =VLOOKUP(AC37,moves!A:D,4,FALSE) -> 4 | AF37: =VLOOKUP(AC37,moves!A:F,5,FALSE) -> transform | AG37: 0 | AH37: 0 | AI37: {=_xlfn.IFS(AG37=1, "starter", AH37=1, "legendary",T37< 13, "weak",T37< 17, "moderate", TRUE, "strong")} -> moderate | AK37: 2 | AL37: 0 | AM37: 3
A38: 414 | B38: Mothim | C38: bug | D38: flying | E38: 70 | F38: 94 | G38: 50 | H38: 94 | I38: 50 | J38: 66 | K38: Moth Pokémon | L38: Forest | M38: Temperate | N38: =(0.4*J38 + 0.5*MAX(F38,H38) + 0.1*MIN(F38,H38)) / 10 -> 8.28 | O38: =(0.4*E38 + 0.3*G38 + 0.3*I38) / 10 -> 5.8 | P38: 0 | Q38: 0 | R38: =ROUND(N38,0)+P38 -> 8 | S38: =ROUND(O38,0)+Q38 -> 6 | T38: =SUM(ROUND(R38,0),ROUND(S38,0)) -> 14 | U38: =C38 -> bug | V38: =IF(D38 = 0, "", D38) -> flying | W38: psychic | X38: ghost | Z38: =IF(ISBLANK(Y38), "", ROUND(( (T39-6)*(T39-7) - (T38-6)*(T38-7) )/15, 0) + 1) | AA38: =B38 -> Mothim | AC38: Lunge | AD38: =VLOOKUP(AC38,moves!A:B,2,FALSE) -> bug | AE38: =VLOOKUP(AC38,moves!A:D,4,FALSE) -> 3 | AF38: =VLOOKUP(AC38,moves!A:F,5,FALSE) -> switch | AG38: 0 | AH38: 0 | AI38: {=_xlfn.IFS(AG38=1, "starter", AH38=1, "legendary",T38< 13, "weak",T38< 17, "moderate", TRUE, "strong")} -> moderate | AK38: 2 | AL38: 0 | AM38: 0
A39: 415 | B39: Combee | C39: bug | D39: flying | E39: 30 | F39: 30 | G39: 42 | H39: 30 | I39: 42 | J39: 70 | K39: Tiny Bee Pokémon | L39: Forest | M39: Temperate | N39: =(0.4*J39 + 0.5*MAX(F39,H39) + 0.1*MIN(F39,H39)) / 10 -> 4.6 | O39: =(0.4*E39 + 0.3*G39 + 0.3*I39) / 10 -> 3.72 | P39: 0 | Q39: 0 | R39: =ROUND(N39,0)+P39 -> 5 | S39: =ROUND(O39,0)+Q39 -> 4 | T39: =SUM(ROUND(R39,0),ROUND(S39,0)) -> 9 | U39: =C39 -> bug | V39: =IF(D39 = 0, "", D39) -> flying | W39: poison | X39: normal | Y39: =B40 -> Vespiquen | Z39: =IF(ISBLANK(Y39), "", ROUND(( (T40-6)*(T40-7) - (T39-6)*(T39-7) )/15, 0) + 1) -> 5 | AA39: =B39 -> Combee | AC39: Sweet Scent | AD39: =VLOOKUP(AC39,moves!A:B,2,FALSE) -> normal | AE39: =VLOOKUP(AC39,moves!A:D,4,FALSE) -> 2 | AF39: =VLOOKUP(AC39,moves!A:F,5,FALSE) -> 0 | AG39: 0 | AH39: 0 | AI39: {=_xlfn.IFS(AG39=1, "starter", AH39=1, "legendary",T39< 13, "weak",T39< 17, "moderate", TRUE, "strong")} -> weak | AK39: 1 | AL39: 0 | AM39: 0
A40: 416 | B40: Vespiquen | C40: bug | D40: flying | E40: 70 | F40: 80 | G40: 102 | H40: 80 | I40: 102 | J40: 40 | K40: Beehive Pokémon | L40: Forest | M40: Temperate | N40: =(0.4*J40 + 0.5*MAX(F40,H40) + 0.1*MIN(F40,H40)) / 10 -> 6.4 | O40: =(0.4*E40 + 0.3*G40 + 0.3*I40) / 10 -> 8.92 | P40: 0 | Q40: 0 | R40: =ROUND(N40,0)+P40 -> 6 | S40: =ROUND(O40,0)+Q40 -> 9 | T40: =SUM(ROUND(R40,0),ROUND(S40,0)) -> 15 | U40: =C40 -> bug | V40: =IF(D40 = 0, "", D40) -> flying | W40: poison | X40: rock | Z40: =IF(ISBLANK(Y40), "", ROUND(( (T41-6)*(T41-7) - (T40-6)*(T40-7) )/15, 0) + 1) | AA40: =B40 -> Vespiquen | AC40: Attack Order | AD40: =VLOOKUP(AC40,moves!A:B,2,FALSE) -> bug | AE40: =VLOOKUP(AC40,moves!A:D,4,FALSE) -> 4 | AF40: =VLOOKUP(AC40,moves!A:F,5,FALSE) -> 0 | AG40: 0 | AH40: 0 | AI40: {=_xlfn.IFS(AG40=1, "starter", AH40=1, "legendary",T40< 13, "weak",T40< 17, "moderate", TRUE, "strong")} -> moderate | AK40: 2 | AL40: 0 | AM40: 0
...

Sheet moves
A1: move_name | B1: move_type | C1: move_power | D1: move_attack_strength | E1: move_class | F1: move_effect | G1: count | H1: min_total | I1: max_total | J1: variance
A2: Struggle Bug | B2: bug | C2: 50 | D2: =IF(NOT(ISBLANK(C2)), IF(ISNUMBER(C2), ROUND((C2 - 5)/20, 0), C2), "") -> 2 | F2: If the user has 3 or less health remaining, this move deals double damage. | G2: {=COUNT(IF(($A2=pokemon!$AC$2:$AC$412)*(pokemon!$AB$2:$AB$412 <> "Noble Form")*(ISBLANK(pokemon!$AJ$2:$AJ$412)), pokemon!$T$2:$T$412))} -> 2 | H2: {=MIN(IF(($A2=pokemon!$AC$2:$AC$412)*(pokemon!$AB$2:$AB$412 <> "Noble Form")*(ISBLANK(pokemon!$AJ$2:$AJ$412)), pokemon!$T$2:$T$412))} -> 7 | I2: {=MAX(IF(($A2=pokemon!$AC$2:$AC$412)*(pokemon!$AB$2:$AB$412 <> "Noble Form")*(ISBLANK(pokemon!$AJ$2:$AJ$412)), pokemon!$T$2:$T$412))} -> 12 | J2: =I2-H2 -> 5
A3: Bug Bite | B3: bug | C3: 60 | D3: =IF(NOT(ISBLANK(C3)), IF(ISNUMBER(C3), ROUND((C3 - 5)/20, 0), C3), "") -> 3 | F3: If the target has a held item, deal 2 extra damage. | G3: {=COUNT(IF(($A3=pokemon!$AC$2:$AC$412)*(pokemon!$AB$2:$AB$412 <> "Noble Form")*(ISBLANK(pokemon!$AJ$2:$AJ$412)), pokemon!$T$2:$T$412))} -> 3 | H3: {=MIN(IF(($A3=pokemon!$AC$2:$AC$412)*(pokemon!$AB$2:$AB$412 <> "Noble Form")*(ISBLANK(pokemon!$AJ$2:$AJ$412)), pokemon!$T$2:$T$412))} -> 7 | I3: {=MAX(IF(($A3=pokemon!$AC$2:$AC$412)*(pokemon!$AB$2:$AB$412 <> "Noble Form")*(ISBLANK(pokemon!$AJ$2:$AJ$412)), pokemon!$T$2:$T$412))} -> 11 | J3: =I3-H3 -> 4
A4: Infatuate | B4: bug | C4: 60 | D4: =IF(NOT(ISBLANK(C4)), IF(ISNUMBER(C4), ROUND((C4 - 5)/20, 0), C4), "") -> 3 | F4: Inflict both the Paralysed and Confused statuses on the target. | G4: {=COUNT(IF(($A4=pokemon!$AC$2:$AC$412)*(pokemon!$AB$2:$AB$412 <> "Noble Form")*(ISBLANK(pokemon!$AJ$2:$AJ$412)), pokemon!$T$2:$T$412))} -> 1 | H4: {=MIN(IF(($A4=pokemon!$AC$2:$AC$412)*(pokemon!$AB$2:$AB$412 <> "Noble Form")*(ISBLANK(pokemon!$AJ$2:$AJ$412)), pokemon!$T$2:$T$412))} -> 28 | I4: {=MAX(IF(($A4=pokemon!$AC$2:$AC$412)*(pokemon!$AB$2:$AB$412 <> "Noble Form")*(ISBLANK(pokemon!$AJ$2:$AJ$412)), pokemon!$T$2:$T$412))} -> 28 | J4: =I4-H4 -> 0
A5: U-Turn | B5: bug | C5: 70 | D5: =IF(NOT(ISBLANK(C5)), IF(ISNUMBER(C5), ROUND((C5 - 5)/20, 0), C5), "") -> 3 | E5: switch | F5: When the target next attacks, remove 1 regular hit from the roll. | G5: {=COUNT(IF(($A5=pokemon!$AC$2:$AC$412)*(pokemon!$AB$2:$AB$412 <> "Noble Form")*(ISBLANK(pokemon!$AJ$2:$AJ$412)), pokemon!$T$2:$T$412))} -> 1 | H5: {=MIN(IF(($A5=pokemon!$AC$2:$AC$412)*(pokemon!$AB$2:$AB$412 <> "Noble Form")*(ISBLANK(pokemon!$AJ$2:$AJ$412)), pokemon!$T$2:$T$412))} -> 11 | I5: {=MAX(IF(($A5=pokemon!$AC$2:$AC$412)*(pokemon!$AB$2:$AB$412 <> "Noble Form")*(ISBLANK(pokemon!$AJ$2:$AJ$412)), pokemon!$T$2:$T$412))} -> 11 | J5: =I5-H5 -> 0
A6: Lunge | B6: bug | C6: 60 | D6: =IF(NOT(ISBLANK(C6)), IF(ISNUMBER(C6), ROUND((C6 - 5)/20, 0), C6), "") -> 3 | E6: switch | F6: This move can be used from your party, the user is switched in immediately. | G6: {=COUNT(IF(($A6=pokemon!$AC$2:$AC$412)*(pokemon!$AB$2:$AB$412 <> "Noble Form")*(ISBLANK(pokemon!$AJ$2:$AJ$412)), pokemon!$T$2:$T$412))} -> 1 | H6: {=MIN(IF(($A6=pokemon!$AC$2:$AC$412)*(pokemon!$AB$2:$AB$412 <> "Noble Form")*(ISBLANK(pokemon!$AJ$2:$AJ$412)), pokemon!$T$2:$T$412))} -> 14 | I6: {=MAX(IF(($A6=pokemon!$AC$2:$AC$412)*(pokemon!$AB$2:$AB$412 <> "Noble Form")*(ISBLANK(pokemon!$AJ$2:$AJ$412)), pokemon!$T$2:$T$412))} -> 14 | J6: =I6-H6 -> 0
A7: X-Scissor | B7: bug | C7: 80 | D7: =IF(NOT(ISBLANK(C7)), IF(ISNUMBER(C7), ROUND((C7 - 5)/20, 0), C7), "") -> 4 | F7: Critical hits deal +1 damage. | G7: {=COUNT(IF(($A7=pokemon!$AC$2:$AC$412)*(pokemon!$AB$2:$AB$412 <> "Noble Form")*(ISBLANK(pokemon!$AJ$2:$AJ$412)), pokemon!$T$2:$T$412))} -> 2 | H7: {=MIN(IF(($A7=pokemon!$AC$2:$AC$412)*(pokemon!$AB$2:$AB$412 <> "Noble Form")*(ISBLANK(pokemon!$AJ$2:$AJ$412)), pokemon!$T$2:$T$412))} -> 14 | I7: {=MAX(IF(($A7=pokemon!$AC$2:$AC$412)*(pokemon!$AB$2:$AB$412 <> "Noble Form")*(ISBLANK(pokemon!$AJ$2:$AJ$412)), pokemon!$T$2:$T$412))} -> 18 | J7: =I7-H7 -> 4
A8: Bug Buzz | B8: bug | C8: 80 | D8: =IF(NOT(ISBLANK(C8)), IF(ISNUMBER(C8), ROUND((C8 - 5)/20, 0), C8), "") -> 4 | F8: If any status symbols are rolled: Inflict the Paralysed status on the target. | G8: {=COUNT(IF(($A8=pokemon!$AC$2:$AC$412)*(pokemon!$AB$2:$AB$412 <> "Noble Form")*(ISBLANK(pokemon!$AJ$2:$AJ$412)), pokemon!$T$2:$T$412))} -> 2 | H8: {=MIN(IF(($A8=pokemon!$AC$2:$AC$412)*(pokemon!$AB$2:$AB$412 <> "Noble Form")*(ISBLANK(pokemon!$AJ$2:$AJ$412)), pokemon!$T$2:$T$412))} -> 13 | I8: {=MAX(IF(($A8=pokemon!$AC$2:$AC$412)*(pokemon!$AB$2:$AB$412 <> "Noble Form")*(ISBLANK(pokemon!$AJ$2:$AJ$412)), pokemon!$T$2:$T$412))} -> 18 | J8: =I8-H8 -> 5
A9: Attack Order | B9: bug | C9: 80 | D9: =IF(NOT(ISBLANK(C9)), IF(ISNUMBER(C9), ROUND((C9 - 5)/20, 0), C9), "") -> 4 | F9: If there is another non-fainted Bug-type Pokémon in your party, deal 2 extra damage. | G9: {=COUNT(IF(($A9=pokemon!$AC$2:$AC$412)*(pokemon!$AB$2:$AB$412 <> "Noble Form")*(ISBLANK(pokemon!$AJ$2:$AJ$412)), pokemon!$T$2:$T$412))} -> 1 | H9: {=MIN(IF(($A9=pokemon!$AC$2:$AC$412)*(pokemon!$AB$2:$AB$412 <> "Noble Form")*(ISBLANK(pokemon!$AJ$2:$AJ$412)), pokemon!$T$2:$T$412))} -> 15 | I9: {=MAX(IF(($A9=pokemon!$AC$2:$AC$412)*(pokemon!$AB$2:$AB$412 <> "Noble Form")*(ISBLANK(pokemon!$AJ$2:$AJ$412)), pokemon!$T$2:$T$412))} -> 15 | J9: =I9-H9 -> 0
A10: Megahorn | B10: bug | C10: 100 | D10: =IF(NOT(ISBLANK(C10)), IF(ISNUMBER(C10), ROUND((C10 - 5)/20, 0), C10), "") -> 5 | F10: Critical hits deal +1 damage but status symbols deal -1 damage. | G10: {=COUNT(IF(($A10=pokemon!$AC$2:$AC$412)*(pokemon!$AB$2:$AB$412 <> "Noble Form")*(ISBLANK(pokemon!$AJ$2:$AJ$412)), pokemon!$T$2:$T$412))} -> 3 | H10: {=MIN(IF(($A10=pokemon!$AC$2:$AC$412)*(pokemon!$AB$2:$AB$412 <> "Noble Form")*(ISBLANK(pokemon!$AJ$2:$AJ$412)), pokemon!$T$2:$T$412))} -> 16 | I10: {=MAX(IF(($A10=pokemon!$AC$2:$AC$412)*(pokemon!$AB$2:$AB$412 <> "Noble Form")*(ISBLANK(pokemon!$AJ$2:$AJ$412)), pokemon!$T$2:$T$412))} -> 18 | J10: =I10-H10 -> 2
A11: Alpha Release | B11: bug | C11: 0 | D11: =IF(NOT(ISBLANK(C11)), IF(ISNUMBER(C11), ROUND((C11 - 5)/20, 0), C11), "") -> 0 | F11: This move does not roll the attack dice. Deal damage equal to 6 minus your current battle fatigue. Increase your battle fatigue by 1. | G11: {=COUNT(IF(($A11=pokemon!$AC$2:$AC$412)*(pokemon!$AB$2:$AB$412 <> "Noble Form")*(ISBLANK(pokemon!$AJ$2:$AJ$412)), pokemon!$T$2:$T$412))} -> 1 | H11: {=MIN(IF(($A11=pokemon!$AC$2:$AC$412)*(pokemon!$AB$2:$AB$412 <> "Noble Form")*(ISBLANK(pokemon!$AJ$2:$AJ$412)), pokemon!$T$2:$T$412))} -> 21 | I11: {=MAX(IF(($A11=pokemon!$AC$2:$AC$412)*(pokemon!$AB$2:$AB$412 <> "Noble Form")*(ISBLANK(pokemon!$AJ$2:$AJ$412)), pokemon!$T$2:$T$412))} -> 21 | J11: =I11-H11 -> 0
A12: Topsy-Turvy | B12: dark | C12: 20 | D12: =IF(NOT(ISBLANK(C12)), IF(ISNUMBER(C12), ROUND((C12 - 5)/20, 0), C12), "") -> 1 | F12: Inflict both the Drowsy and Confused statuses on the target. | G12: {=COUNT(IF(($A12=pokemon!$AC$2:$AC$412)*(pokemon!$AB$2:$AB$412 <> "Noble Form")*(ISBLANK(pokemon!$AJ$2:$AJ$412)), pokemon!$T$2:$T$412))} -> 1 | H12: {=MIN(IF(($A12=pokemon!$AC$2:$AC$412)*(pokemon!$AB$2:$AB$412 <> "Noble Form")*(ISBLANK(pokemon!$AJ$2:$AJ$412)), pokemon!$T$2:$T$412))} -> 10 | I12: {=MAX(IF(($A12=pokemon!$AC$2:$AC$412)*(pokemon!$AB$2:$AB$412 <> "Noble Form")*(ISBLANK(pokemon!$AJ$2:$AJ$412)), pokemon!$T$2:$T$412))} -> 10 | J12: =I12-H12 -> 0
A13: Soul Siphon | B13: dark | C13: 100 | D13: =IF(NOT(ISBLANK(C13)), IF(ISNUMBER(C13), ROUND((C13 - 5)/20, 0), C13), "") -> 5 | E13: trap | F13: Heal damage equal to the current battle fatigue of the target. | G13: {=COUNT(IF(($A13=pokemon!$AC$2:$AC$412)*(pokemon!$AB$2:$AB$412 <> "Noble Form")*(ISBLANK(pokemon!$AJ$2:$AJ$412)), pokemon!$T$2:$T$412))} -> 1 | H13: {=MIN(IF(($A13=pokemon!$AC$2:$AC$412)*(pokemon!$AB$2:$AB$412 <> "Noble Form")*(ISBLANK(pokemon!$AJ$2:$AJ$412)), pokemon!$T$2:$T$412))} -> 20 | I13: {=MAX(IF(($A13=pokemon!$AC$2:$AC$412)*(pokemon!$AB$2:$AB$412 <> "Noble Form")*(ISBLANK(pokemon!$AJ$2:$AJ$412)), pokemon!$T$2:$T$412))} -> 20 | J13: =I13-H13 -> 0
A14: Dark Void | B14: dark | C14: 40 | D14: =IF(NOT(ISBLANK(C14)), IF(ISNUMBER(C14), ROUND((C14 - 5)/20, 0), C14), "") -> 2 | E14: agile | F14: Inflict the Drowsy status on the target and all Pokémon in the target party. | G14: {=COUNT(IF(($A14=pokemon!$AC$2:$AC$412)*(pokemon!$AB$2:$AB$412 <> "Noble Form")*(ISBLANK(pokemon!$AJ$2:$AJ$412)), pokemon!$T$2:$T$412))} -> 1 | H14: {=MIN(IF(($A14=pokemon!$AC$2:$AC$412)*(pokemon!$AB$2:$AB$412 <> "Noble Form")*(ISBLANK(pokemon!$AJ$2:$AJ$412)), pokemon!$T$2:$T$412))} -> 20 | I14: {=MAX(IF(($A14=pokemon!$AC$2:$AC$412)*(pokemon!$AB$2:$AB$412 <> "Noble Form")*(ISBLANK(pokemon!$AJ$2:$AJ$412)), pokemon!$T$2:$T$412))} -> 20 | J14: =I14-H14 -> 0
A15: Bite | B15: dark | C15: 60 | D15: =IF(NOT(ISBLANK(C15)), IF(ISNUMBER(C15), ROUND((C15 - 5)/20, 0), C15), "") -> 3 | F15: When the target is next attacked, add 1 regular hit to the roll. | G15: {=COUNT(IF(($A15=pokemon!$AC$2:$AC$412)*(pokemon!$AB$2:$AB$412 <> "Noble Form")*(ISBLANK(pokemon!$AJ$2:$AJ$412)), pokemon!$T$2:$T$412))} -> 6 | H15: {=MIN(IF(($A15=pokemon!$AC$2:$AC$412)*(pokemon!$AB$2:$AB$412 <> "Noble Form")*(ISBLANK(pokemon!$AJ$2:$AJ$412)), pokemon!$T$2:$T$412))} -> 11 | I15: {=MAX(IF(($A15=pokemon!$AC$2:$AC$412)*(pokemon!$AB$2:$AB$412 <> "Noble Form")*(ISBLANK(pokemon!$AJ$2:$AJ$412)), pokemon!$T$2:$T$412))} -> 14 | J15: =I15-H15 -> 3
A16: Night Slash | B16: dark | C16: 75 | D16: =IF(NOT(ISBLANK(C16)), IF(ISNUMBER(C16), ROUND((C16 - 5)/20, 0), C16), "") -> 4 | F16: Critical hits deal +1 damage. | G16: {=COUNT(IF(($A16=pokemon!$AC$2:$AC$412)*(pokemon!$AB$2:$AB$412 <> "Noble Form")*(ISBLANK(pokemon!$AJ$2:$AJ$412)), pokemon!$T$2:$T$412))} -> 3 | H16: {=MIN(IF(($A16=pokemon!$AC$2:$AC$412)*(pokemon!$AB$2:$AB$412 <> "Noble Form")*(ISBLANK(pokemon!$AJ$2:$AJ$412)), pokemon!$T$2:$T$412))} -> 16 | I16: {=MAX(IF(($A16=pokemon!$AC$2:$AC$412)*(pokemon!$AB$2:$AB$412 <> "Noble Form")*(ISBLANK(pokemon!$AJ$2:$AJ$412)), pokemon!$T$2:$T$412))} -> 17 | J16: =I16-H16 -> 1
A17: Crunch | B17: dark | C17: 80 | D17: =IF(NOT(ISBLANK(C17)), IF(ISNUMBER(C17), ROUND((C17 - 5)/20, 0), C17), "") -> 4 | F17: When the target is next attacked, add 1 regular hit to the roll. | G17: {=COUNT(IF(($A17=pokemon!$AC$2:$AC$412)*(pokemon!$AB$2:$AB$412 <> "Noble Form")*(ISBLANK(pokemon!$AJ$2:$AJ$412)), pokemon!$T$2:$T$412))} -> 3 | H17: {=MIN(IF(($A17=pokemon!$AC$2:$AC$412)*(pokemon!$AB$2:$AB$412 <> "Noble Form")*(ISBLANK(pokemon!$AJ$2:$AJ$412)), pokemon!$T$2:$T$412))} -> 14 | I17: {=MAX(IF(($A17=pokemon!$AC$2:$AC$412)*(pokemon!$AB$2:$AB$412 <> "Noble Form")*(ISBLANK(pokemon!$AJ$2:$AJ$412)), pokemon!$T$2:$T$412))} -> 18 | J17: =I17-H17 -> 4
A18: Hangry Wheel | B18: dark | C18: 60 | D18: =IF(NOT(ISBLANK(C18)), IF(ISNUMBER(C18), ROUND((C18 - 5)/20, 0), C18), "") -> 3 | E18: transform | F18: Inflict the Drowsy status on the target. | G18: {=COUNT(IF(($A18=pokemon!$AC$2:$AC$412)*(pokemon!$AB$2:$AB$412 <> "Noble Form")*(ISBLANK(pokemon!$AJ$2:$AJ$412)), pokemon!$T$2:$T$412))} -> 1 | H18: {=MIN(IF(($A18=pokemon!$AC$2:$AC$412)*(pokemon!$AB$2:$AB$412 <> "Noble Form")*(ISBLANK(pokemon!$AJ$2:$AJ$412)), pokemon!$T$2:$T$412))} -> 15 | I18: {=MAX(IF(($A18=pokemon!$AC$2:$AC$412)*(pokemon!$AB$2:$AB$412 <> "Noble Form")*(ISBLANK(pokemon!$AJ$2:$AJ$412)), pokemon!$T$2:$T$412))} -> 15 | J18: =I18-H18 -> 0
A19: Night Daze | B19: dark | C19: 100 | D19: =IF(NOT(ISBLANK(C19)), IF(ISNUMBER(C19), ROUND((C19 - 5)/20, 0), C19), "") -> 5 | F19: If 2 or more status symbols are rolled: Inflict the Drowsy status on the target. | G19: {=COUNT(IF(($A19=pokemon!$AC$2:$AC$412)*(pokemon!$AB$2:$AB$412 <> "Noble Form")*(ISBLANK(pokemon!$AJ$2:$AJ$412)), pokemon!$T$2:$T$412))} -> 1 | H19: {=MIN(IF(($A19=pokemon!$AC$2:$AC$412)*(pokemon!$AB$2:$AB$412 <> "Noble Form")*(ISBLANK(pokemon!$AJ$2:$AJ$412)), pokemon!$T$2:$T$412))} -> 17 | I19: {=MAX(IF(($A19=pokemon!$AC$2:$AC$412)*(pokemon!$AB$2:$AB$412 <> "Noble Form")*(ISBLANK(pokemon!$AJ$2:$AJ$412)), pokemon!$T$2:$T$412))} -> 17 | J19: =I19-H19 -> 0
A20: Chomp | B20: dark | C20: 100 | D20: =IF(NOT(ISBLANK(C20)), IF(ISNUMBER(C20), ROUND((C20 - 5)/20, 0), C20), "") -> 5 | F20: When the target is next attacked, add 1 regular hit to the roll. | G20: {=COUNT(IF(($A20=pokemon!$AC$2:$AC$412)*(pokemon!$AB$2:$AB$412 <> "Noble Form")*(ISBLANK(pokemon!$AJ$2:$AJ$412)), pokemon!$T$2:$T$412))} -> 1 | H20: {=MIN(IF(($A20=pokemon!$AC$2:$AC$412)*(pokemon!$AB$2:$AB$412 <> "Noble Form")*(ISBLANK(pokemon!$AJ$2:$AJ$412)), pokemon!$T$2:$T$412))} -> 28 | I20: {=MAX(IF(($A20=pokemon!$AC$2:$AC$412)*(pokemon!$AB$2:$AB$412 <> "Noble Form")*(ISBLANK(pokemon!$AJ$2:$AJ$412)), pokemon!$T$2:$T$412))} -> 28 | J20: =I20-H20 -> 0
A21: Foul Play | B21: dark | C21: ? | D21: =IF(NOT(ISBLANK(C21)), IF(ISNUMBER(C21), ROUND((C21 - 5)/20, 0), C21), "") -> ? | F21: Copy the attack strength of a move the target knows. Minimum 1 attack strength. | G21: {=COUNT(IF(($A21=pokemon!$AC$2:$AC$412)*(pokemon!$AB$2:$AB$412 <> "Noble Form")*(ISBLANK(pokemon!$AJ$2:$AJ$412)), pokemon!$T$2:$T$412))} -> 1 | H21: {=MIN(IF(($A21=pokemon!$AC$2:$AC$412)*(pokemon!$AB$2:$AB$412 <> "Noble Form")*(ISBLANK(pokemon!$AJ$2:$AJ$412)), pokemon!$T$2:$T$412))} -> 11 | I21: {=MAX(IF(($A21=pokemon!$AC$2:$AC$412)*(pokemon!$AB$2:$AB$412 <> "Noble Form")*(ISBLANK(pokemon!$AJ$2:$AJ$412)), pokemon!$T$2:$T$412))} -> 11 | J21: =I21-H21 -> 0
A22: Aura Storm | B22: dark | C22: 80 | D22: =IF(NOT(ISBLANK(C22)), IF(ISNUMBER(C22), ROUND((C22 - 5)/20, 0), C22), "") -> 4 | F22: Status symbols deal +1 damage. | G22: {=COUNT(IF(($A22=pokemon!$AC$2:$AC$412)*(pokemon!$AB$2:$AB$412 <> "Noble Form")*(ISBLANK(pokemon!$AJ$2:$AJ$412)), pokemon!$T$2:$T$412))} -> 1 | H22: {=MIN(IF(($A22=pokemon!$AC$2:$AC$412)*(pokemon!$AB$2:$AB$412 <> "Noble Form")*(ISBLANK(pokemon!$AJ$2:$AJ$412)), pokemon!$T$2:$T$412))} -> 21 | I22: {=MAX(IF(($A22=pokemon!$AC$2:$AC$412)*(pokemon!$AB$2:$AB$412 <> "Noble Form")*(ISBLANK(pokemon!$AJ$2:$AJ$412)), pokemon!$T$2:$T$412))} -> 21 | J22: =I22-H22 -> 0
A23: Twister | B23: dragon | C23: 45 | D23: =IF(NOT(ISBLANK(C23)), IF(ISNUMBER(C23), ROUND((C23 - 5)/20, 0), C23), "") -> 2 | F23: Inflict the Paralysed status on the target. | G23: {=COUNT(IF(($A23=pokemon!$AC$2:$AC$412)*(pokemon!$AB$2:$AB$412 <> "Noble Form")*(ISBLANK(pokemon!$AJ$2:$AJ$412)), pokemon!$T$2:$T$412))} -> 1 | H23: {=MIN(IF(($A23=pokemon!$AC$2:$AC$412)*(pokemon!$AB$2:$AB$412 <> "Noble Form")*(ISBLANK(pokemon!$AJ$2:$AJ$412)), pokemon!$T$2:$T$412))} -> 10 | I23: {=MAX(IF(($A23=pokemon!$AC$2:$AC$412)*(pokemon!$AB$2:$AB$412 <> "Noble Form")*(ISBLANK(pokemon!$AJ$2:$AJ$412)), pokemon!$T$2:$T$412))} -> 10 | J23: =I23-H23 -> 0
A24: Dual Chop | B24: dragon | C24: 40 | D24: =IF(NOT(ISBLANK(C24)), IF(ISNUMBER(C24), ROUND((C24 - 5)/20, 0), C24), "") -> 2 | F24: Regular hits deal +1 damage. | G24: {=COUNT(IF(($A24=pokemon!$AC$2:$AC$412)*(pokemon!$AB$2:$AB$412 <> "Noble Form")*(ISBLANK(pokemon!$AJ$2:$AJ$412)), pokemon!$T$2:$T$412))} -> 1 | H24: {=MIN(IF(($A24=pokemon!$AC$2:$AC$412)*(pokemon!$AB$2:$AB$412 <> "Noble Form")*(ISBLANK(pokemon!$AJ$2:$AJ$412)), pokemon!$T$2:$T$412))} -> 14 | I24: {=MAX(IF(($A24=pokemon!$AC$2:$AC$412)*(pokemon!$AB$2:$AB$412 <> "Noble Form")*(ISBLANK(pokemon!$AJ$2:$AJ$412)), pokemon!$T$2:$T$412))} -> 14 | J24: =I24-H24 -> 0
A25: Dragon Breath | B25: dragon | C25: 60 | D25: =IF(NOT(ISBLANK(C25)), IF(ISNUMBER(C25), ROUND((C25 - 5)/20, 0), C25), "") -> 3 | F25: If any status symbols are rolled: Inflict the Burned status on the target. | G25: {=COUNT(IF(($A25=pokemon!$AC$2:$AC$412)*(pokemon!$AB$2:$AB$412 <> "Noble Form")*(ISBLANK(pokemon!$AJ$2:$AJ$412)), pokemon!$T$2:$T$412))} -> 1 | H25: {=MIN(IF(($A25=pokemon!$AC$2:$AC$412)*(pokemon!$AB$2:$AB$412 <> "Noble Form")*(ISBLANK(pokemon!$AJ$2:$AJ$412)), pokemon!$T$2:$T$412))} -> 10 | I25: {=MAX(IF(($A25=pokemon!$AC$2:$AC$412)*(pokemon!$AB$2:$AB$412 <> "Noble Form")*(ISBLANK(pokemon!$AJ$2:$AJ$412)), pokemon!$T$2:$T$412))} -> 10 | J25: =I25-H25 -> 0
A26: Spacial Rend | B26: dragon | C26: 90 | D26: =IF(NOT(ISBLANK(C26)), IF(ISNUMBER(C26), ROUND((C26 - 5)/20, 0), C26), "") -> 4 | F26: Critical hits deal +2 damage. | G26: {=COUNT(IF(($A26=pokemon!$AC$2:$AC$412)*(pokemon!$AB$2:$AB$412 <> "Noble Form")*(ISBLANK(pokemon!$AJ$2:$AJ$412)), pokemon!$T$2:$T$412))} -> 1 | H26: {=MIN(IF(($A26=pokemon!$AC$2:$AC$412)*(pokemon!$AB$2:$AB$412 <> "Noble Form")*(ISBLANK(pokemon!$AJ$2:$AJ$412)), pokemon!$T$2:$T$412))} -> 23 | I26: {=MAX(IF(($A26=pokemon!$AC$2:$AC$412)*(pokemon!$AB$2:$AB$412 <> "Noble Form")*(ISBLANK(pokemon!$AJ$2:$AJ$412)), pokemon!$T$2:$T$412))} -> 23 | J26: =I26-H26 -> 0
A27: Dragon Pulse | B27: dragon | C27: 80 | D27: =IF(NOT(ISBLANK(C27)), IF(ISNUMBER(C27), ROUND((C27 - 5)/20, 0), C27), "") -> 4 | F27: Status symbols deal +1 damage. | G27: {=COUNT(IF(($A27=pokemon!$AC$2:$AC$412)*(pokemon!$AB$2:$AB$412 <> "Noble Form")*(ISBLANK(pokemon!$AJ$2:$AJ$412)), pokemon!$T$2:$T$412))} -> 3 | H27: {=MIN(IF(($A27=pokemon!$AC$2:$AC$412)*(pokemon!$AB$2:$AB$412 <> "Noble Form")*(ISBLANK(pokemon!$AJ$2:$AJ$412)), pokemon!$T$2:$T$412))} -> 16 | I27: {=MAX(IF(($A27=pokemon!$AC$2:$AC$412)*(pokemon!$AB$2:$AB$412 <> "Noble Form")*(ISBLANK(pokemon!$AJ$2:$AJ$412)), pokemon!$T$2:$T$412))} -> 20 | J27: =I27-H27 -> 4
A28: Draco Meteor | B28: dragon | C28: 100 | D28: =IF(NOT(ISBLANK(C28)), IF(ISNUMBER(C28), ROUND((C28 - 5)/20, 0), C28), "") -> 5 | F28: During this attack and when the user is next attacked, status symbols deal +1 damage. | G28: {=COUNT(IF(($A28=pokemon!$AC$2:$AC$412)*(pokemon!$AB$2:$AB$412 <> "Noble Form")*(ISBLANK(pokemon!$AJ$2:$AJ$412)), pokemon!$T$2:$T$412))} -> 1 | H28: {=MIN(IF(($A28=pokemon!$AC$2:$AC$412)*(pokemon!$AB$2:$AB$412 <> "Noble Form")*(ISBLANK(pokemon!$AJ$2:$AJ$412)), pokemon!$T$2:$T$412))} -> 20 | I28: {=MAX(IF(($A28=pokemon!$AC$2:$AC$412)*(pokemon!$AB$2:$AB$412 <> "Noble Form")*(ISBLANK(pokemon!$AJ$2:$AJ$412)), pokemon!$T$2:$T$412))} -> 20 | J28: =I28-H28 -> 0
A29: Dragon Rush | B29: dragon | C29: 100 | D29: =IF(NOT(ISBLANK(C29)), IF(ISNUMBER(C29), ROUND((C29 - 5)/20, 0), C29), "") -> 5 | F29: If 2 or more status symbols are rolled: Inflict the Paralysed status on the target. | G29: {=COUNT(IF(($A29=pokemon!$AC$2:$AC$412)*(pokemon!$AB$2:$AB$412 <> "Noble Form")*(ISBLANK(pokemon!$AJ$2:$AJ$412)), pokemon!$T$2:$T$412))} -> 2 | H29: {=MIN(IF(($A29=pokemon!$AC$2:$AC$412)*(pokemon!$AB$2:$AB$412 <> "Noble Form")*(ISBLANK(pokemon!$AJ$2:$AJ$412)), pokemon!$T$2:$T$412))} -> 20 | I29: {=MAX(IF(($A29=pokemon!$AC$2:$AC$412)*(pokemon!$AB$2:$AB$412 <> "Noble Form")*(ISBLANK(pokemon!$AJ$2:$AJ$412)), pokemon!$T$2:$T$412))} -> 20 | J29: =I29-H29 -> 0
A30: Renegade Fury | B30: dragon | C30: 100 | D30: =IF(NOT(ISBLANK(C30)), IF(ISNUMBER(C30), ROUND((C30 - 5)/20, 0), C30), "") -> 5 | F30: If the target faints, any remaining damage from this attack is applied to the next Pokémon switched in. | G30: {=COUNT(IF(($A30=pokemon!$AC$2:$AC$412)*(pokemon!$AB$2:$AB$412 <> "Noble Form")*(ISBLANK(pokemon!$AJ$2:$AJ$412)), pokemon!$T$2:$T$412))} -> 1 | H30: {=MIN(IF(($A30=pokemon!$AC$2:$AC$412)*(pokemon!$AB$2:$AB$412 <> "Noble Form")*(ISBLANK(pokemon!$AJ$2:$AJ$412)), pokemon!$T$2:$T$412))} -> 24 | I30: {=MAX(IF(($A30=pokemon!$AC$2:$AC$412)*(pokemon!$AB$2:$AB$412 <> "Noble Form")*(ISBLANK(pokemon!$AJ$2:$AJ$412)), pokemon!$T$2:$T$412))} -> 24 | J30: =I30-H30 -> 0
A31: Outrage | B31: dragon | C31: 100 | D31: =IF(NOT(ISBLANK(C31)), IF(ISNUMBER(C31), ROUND((C31 - 5)/20, 0), C31), "") -> 5 | F31: Inflict the Confused status on the user. Deal any damage taken by the user during this attack to the target as well. | G31: {=COUNT(IF(($A31=pokemon!$AC$2:$AC$412)*(pokemon!$AB$2:$AB$412 <> "Noble Form")*(ISBLANK(pokemon!$AJ$2:$AJ$412)), pokemon!$T$2:$T$412))} -> 2 | H31: {=MIN(IF(($A31=pokemon!$AC$2:$AC$412)*(pokemon!$AB$2:$AB$412 <> "Noble Form")*(ISBLANK(pokemon!$AJ$2:$AJ$412)), pokemon!$T$2:$T$412))} -> 19 | I31: {=MAX(IF(($A31=pokemon!$AC$2:$AC$412)*(pokemon!$AB$2:$AB$412 <> "Noble Form")*(ISBLANK(pokemon!$AJ$2:$AJ$412)), pokemon!$T$2:$T$412))} -> 20 | J31: =I31-H31 -> 1
A32: Roar of Time | B32: dragon | C32: 120 | D32: =IF(NOT(ISBLANK(C32)), IF(ISNUMBER(C32), ROUND((C32 - 5)/20, 0), C32), "") -> 6 | E32: decisive | F32: Increase the battle fatigue of the user by 1. | G32: {=COUNT(IF(($A32=pokemon!$AC$2:$AC$412)*(pokemon!$AB$2:$AB$412 <> "Noble Form")*(ISBLANK(pokemon!$AJ$2:$AJ$412)), pokemon!$T$2:$T$412))} -> 1 | H32: {=MIN(IF(($A32=pokemon!$AC$2:$AC$412)*(pokemon!$AB$2:$AB$412 <> "Noble Form")*(ISBLANK(pokemon!$AJ$2:$AJ$412)), pokemon!$T$2:$T$412))} -> 23 | I32: {=MAX(IF(($A32=pokemon!$AC$2:$AC$412)*(pokemon!$AB$2:$AB$412 <> "Noble Form")*(ISBLANK(pokemon!$AJ$2:$AJ$412)), pokemon!$T$2:$T$412))} -> 23 | J32: =I32-H32 -> 0
A33: Dragon Boom | B33: dragon | C33: 80 | D33: =IF(NOT(ISBLANK(C33)), IF(ISNUMBER(C33), ROUND((C33 - 5)/20, 0), C33), "") -> 4 | F33: If any status symbols are rolled: Inflict the Paralysed status on the target. | G33: {=COUNT(IF(($A33=pokemon!$AC$2:$AC$412)*(pokemon!$AB$2:$AB$412 <> "Noble Form")*(ISBLANK(pokemon!$AJ$2:$AJ$412)), pokemon!$T$2:$T$412))} -> 1 | H33: {=MIN(IF(($A33=pokemon!$AC$2:$AC$412)*(pokemon!$AB$2:$AB$412 <> "Noble Form")*(ISBLANK(pokemon!$AJ$2:$AJ$412)), pokemon!$T$2:$T$412))} -> 21 | I33: {=MAX(IF(($A33=pokemon!$AC$2:$AC$412)*(pokemon!$AB$2:$AB$412 <> "Noble Form")*(ISBLANK(pokemon!$AJ$2:$AJ$412)), pokemon!$T$2:$T$412))} -> 21 | J33: =I33-H33 -> 0
A34: Maw Protocol | B34: dragon | C34: 60 | D34: =IF(NOT(ISBLANK(C34)), IF(ISNUMBER(C34), ROUND((C34 - 5)/20, 0), C34), "") -> 3 | E34: boost | F34: Increase the initiative of the user by 3 and the attack strength of their moves by 1. | G34: {=COUNT(IF(($A34=pokemon!$AC$2:$AC$412)*(pokemon!$AB$2:$AB$412 <> "Noble Form")*(ISBLANK(pokemon!$AJ$2:$AJ$412)), pokemon!$T$2:$T$412))} -> 1 | H34: {=MIN(IF(($A34=pokemon!$AC$2:$AC$412)*(pokemon!$AB$2:$AB$412 <> "Noble Form")*(ISBLANK(pokemon!$AJ$2:$AJ$412)), pokemon!$T$2:$T$412))} -> 20 | I34: {=MAX(IF(($A34=pokemon!$AC$2:$AC$412)*(pokemon!$AB$2:$AB$412 <> "Noble Form")*(ISBLANK(pokemon!$AJ$2:$AJ$412)), pokemon!$T$2:$T$412))} -> 20 | J34: =I34-H34 -> 0
A35: Nuzzle | B35: electric | C35: 20 | D35: =IF(NOT(ISBLANK(C35)), IF(ISNUMBER(C35), ROUND((C35 - 5)/20, 0), C35), "") -> 1 | E35: agile | F35: Inflict the Paralysed status on the target. | G35: {=COUNT(IF(($A35=pokemon!$AC$2:$AC$412)*(pokemon!$AB$2:$AB$412 <> "Noble Form")*(ISBLANK(pokemon!$AJ$2:$AJ$412)), pokemon!$T$2:$T$412))} -> 2 | H35: {=MIN(IF(($A35=pokemon!$AC$2:$AC$412)*(pokemon!$AB$2:$AB$412 <> "Noble Form")*(ISBLANK(pokemon!$AJ$2:$AJ$412)), pokemon!$T$2:$T$412))} -> 10 | I35: {=MAX(IF(($A35=pokemon!$AC$2:$AC$412)*(pokemon!$AB$2:$AB$412 <> "Noble Form")*(ISBLANK(pokemon!$AJ$2:$AJ$412)), pokemon!$T$2:$T$412))} -> 14 | J35: =I35-H35 -> 4
A36: Ion Deluge | B36: electric | C36: 40 | D36: =IF(NOT(ISBLANK(C36)), IF(ISNUMBER(C36), ROUND((C36 - 5)/20, 0), C36), "") -> 2 | F36: Inflict both the Paralysed and Poisoned statuses on the target. | G36: {=COUNT(IF(($A36=pokemon!$AC$2:$AC$412)*(pokemon!$AB$2:$AB$412 <> "Noble Form")*(ISBLANK(pokemon!$AJ$2:$AJ$412)), pokemon!$T$2:$T$412))} -> 1 | H36: {=MIN(IF(($A36=pokemon!$AC$2:$AC$412)*(pokemon!$AB$2:$AB$412 <> "Noble Form")*(ISBLANK(pokemon!$AJ$2:$AJ$412)), pokemon!$T$2:$T$412))} -> 17 | I36: {=MAX(IF(($A36=pokemon!$AC$2:$AC$412)*(pokemon!$AB$2:$AB$412 <> "Noble Form")*(ISBLANK(pokemon!$AJ$2:$AJ$412)), pokemon!$T$2:$T$412))} -> 17 | J36: =I36-H36 -> 0
